Workbook

Sheet LIN Milestones 2025-26 Season
A1: Player | B1: Milestone Type | C1: Milestone | D1: Current Total | E1: Distance | F1: Number to Achieve | G1: Ranking & Player Passing | H1: Next Up | I1: Graphic? | J1: Request
A2: Trevon Scott | B2: LIN | C2: Steals | D2: ='Trevon Scott'!E5 -> 101 | E2: =F2-D2 -> 2 | F2: 103 | G2: #4, Passing Chris Chiozza (102)
A3: Terry Roberts | B3: LIN | C3: Games Played | D3: ='Terry Roberts'!B12 -> 90 | E3: =F3-D3 -> 3 | F3: 93 | G3: #4, Passing J.J. Moore (92)
A4: Tyson Etienne | B4: LIN | C4: Steals | D4: ='Tyson Etienne'!E5 -> 100 | E4: =F4-D4 -> 3 | F4: 103 | G4: #4, Passing Chris Chiozza (102)
A5: Mfon Udofia | B5: LIN | C5: Wins | D5: ='Mfon Udofia'!C2 -> 72 | E5: =F5-D5 -> 3 | F5: 75
A6: David Muoka | B6: LIN | C6: Blocks | D6: ='David Muoka'!E6 -> 96 | E6: =F6-D6 -> 4 | F6: 100 | G6: #1 In Franchise History
A7: D'Andre Davis | B7: Career | C7: Rebounds | D7: ='D''Andre Davis'!B3 -> 96 | E7: =F7-D7 -> 4 | F7: 100
A8: Ben Saraf | B8: Career | C8: Assists | D8: ='Ben Saraf'!B4 -> 95 | E8: =F8-D8 -> 5 | F8: 100
A9: David Muoka | B9: Career | C9: Blocks | D9: ='David Muoka'!B6 -> 194 | E9: =F9-D9 -> 6 | F9: 200
A10: Tyson Etienne | B10: LIN | C10: Assists | D10: ='Tyson Etienne'!E4 -> 294 | E10: =F10-D10 -> 6 | F10: 300
A11: Terry Roberts | B11: Career | C11: Steals | D11: ='Terry Roberts'!B5 -> 109 | E11: =F11-D11 -> 6 | F11: 115 | G11: #2, Passing Tahjere McCall (114)
A12: David Muoka | B12: LIN | C12: Games Played | D12: ='David Muoka'!E12 -> 83 | E12: =F12-D12 -> 7 | F12: 90
A13: Josh Minott | B13: Career | C13: Assists | D13: ='Josh Minott'!B4 -> 92 | E13: =F13-D13 -> 8 | F13: 100
A14: Javon Freeman-Liberty | B14: Career | C14: Steals | D14: ='Javon Freeman-Liberty'!B5 -> 92 | E14: =F14-D14 -> 8 | F14: 100
A15: Trevon Scott | B15: LIN | C15: Games Played | D15: ='Trevon Scott'!E12 -> 81 | E15: =F15-D15 -> 9 | F15: 90 | G15: #5, Passing Jordan Bowden (89)
A16: Tyson Etienne | B16: LIN | C16: Games Played | D16: ='Tyson Etienne'!E12 -> 80 | E16: =F16-D16 -> 10 | F16: 90 | G16: #5, Passing Jordan Bowden (89)
A17: Yuri Collins | B17: Career | C17: Rebounds | D17: ='Yuri Collins'!B3 -> 332 | E17: =F17-D17 -> 18 | F17: 350
A18: Tyson Etienne | B18: LIN | C18: Rebounds | D18: ='Tyson Etienne'!E3 -> 240 | E18: =F18-D18 -> 10 | F18: 250
A19: Yuri Collins | B19: Career | C19: Steals | D19: ='Yuri Collins'!B5 -> 126 | E19: =F19-D19 -> 24 | F19: 150
A20: Malachi Smith | B20: Career | C20: Rebounds | D20: ='Malachi Smith'!B3 -> 588 | E20: =F20-D20 -> 12 | F20: 600
A21: Malachi Smith | B21: Career | C21: Assists | D21: ='Malachi Smith'!B4 -> 487 | E21: =F21-D21 -> 13 | F21: 500
A22: Hunter Cattoor | B22: Career | C22: Points | D22: ='Hunter Cattoor'!B2 -> 287 | E22: =F22-D22 -> 13 | F22: 300
A23: Nolan Traore | B23: Career | C23: Assists | D23: ='Nolan Traore'!B4 -> 85 | E23: =F23-D23 -> 15 | F23: 100
A24: Trevon Scott | B24: Career | C24: Blocks | D24: ='Trevon Scott'!B6 -> 82 | E24: =F24-D24 -> 18 | F24: 100
A25: E.J. Liddell | B25: Career | C25: Rebounds | D25: ='E.J. Liddell'!B3 -> 682 | E25: =F25-D25 -> 18 | F25: 700
A26: Malachi Smith | B26: Career | C26: Steals | D26: ='Malachi Smith'!B5 -> 130 | E26: =F26-D26 -> 20 | F26: 150
A27: Terry Roberts | B27: Career | C27: Points | D27: ='Terry Roberts'!B2 -> 580 | E27: =F27-D27 -> 20 | F27: 600
A28: Trevon Scott | B28: LIN | C28: 3PM | D28: ='Trevon Scott'!E8 -> 128 | E28: =F28-D28 -> 21 | F28: 149 | G28: #5, Passing Milton Doyle (148)
A29: Chaney Johnson | B29: Career | C29: Assists | D29: ='Chaney Johnson'!B4 -> 78 | E29: =F29-D29 -> 22 | F29: 100
A30: Ben Saraf | B30: Career | C30: Rebounds | D30: ='Ben Saraf'!B3 -> 76 | E30: =F30-D30 -> 24 | F30: 100
A31: Javon Freeman-Liberty | B31: Career | C31: Assists | D31: ='Javon Freeman-Liberty'!B4 -> 275 | E31: =F31-D31 -> 25 | F31: 300
A32: E.J. Liddell | B32: Career | C32: Assists | D32: ='E.J. Liddell'!B4 -> 175 | E32: =F32-D32 -> 25 | F32: 200
A33: Trevon Scott | B33: Career | C33: Steals | D33: ='Trevon Scott'!B5 -> 221 | E33: =F33-D33 -> 29 | F33: 250
A34: Trevon Scott | B34: LIN | C34: Rebounds | D34: ='Trevon Scott'!E3 -> 468 | E34: =F34-D34 -> 32 | F34: 500
A35: Jahlil White | B35: Career | C35: Points | D35: ='Jahlil White'!B2 -> 65 | E35: =F35-D35 -> 35 | F35: 100
A36: Tyson Etienne | B36: LIN | C36: 3PM | D36: ='Tyson Etienne'!E8 -> 264 | E36: =F36-D36 -> 36 | F36: 300 | G36: #1 In Franchise History
A37: Alex Schumacher | B37: Career | C37: Steals | D37: ='Alex Schumacher'!B5 -> 64 | E37: =F37-D37 -> 36 | F37: 100
A38: Hunter Cattoor | B38: Career | C38: Rebounds | D38: ='Hunter Cattoor'!B3 -> 64 | E38: =F38-D38 -> 36 | F38: 100
A39: Alex Schumacher | B39: Career | C39: Assists | D39: ='Alex Schumacher'!B4 -> 264 | E39: =F39-D39 -> 36 | F39: 300
A40: Danny Wolf | B40: Career | C40: Rebounds | D40: ='Danny Wolf'!B3 -> 63 | E40: =F40-D40 -> 37 | F40: 100
...

Sheet LIN Playoff Milestones 2025-26
A1: Player | B1: Milestone Type | C1: Milestone | D1: Current Total | E1: Distance | F1: Number to Achieve | G1: Ranking & Player Passing | H1: Next Up | I1: Graphic? | J1: Request
A2: David Muoka | B2: LIN | C2: Double-Doubles | D2: ='David Muoka'!B23 -> 0 | E2: =F2-D2 -> 2 | F2: 2 | G2: #2, Passing Chris Chiozza (1)
A3: Trevon Scott | B3: LIN | C3: Double-Doubles | D3: ='Trevon Scott'!B23 -> 0 | E3: =F3-D3 -> 2 | F3: 2 | G3: #2, Passing Chris Chiozza (1)
A4: Terry Roberts | B4: LIN | C4: Double-Doubles | D4: ='Terry Roberts'!B23 -> 0 | E4: =F4-D4 -> 2 | F4: 2 | G4: #1, Passing Chris Chiozza (1)
A5: E.J. Liddell | B5: LIN | C5: Double-Doubles | D5: ='E.J. Liddell'!B23 -> 0 | E5: =F5-D5 -> 2 | F5: 2 | G5: #2, Passing Chris Chiozza (1)
A6: Chaney Johnson | B6: LIN | C6: Double-Doubles | D6: ='Chaney Johnson'!B23 -> 0 | E6: =F6-D6 -> 2 | F6: 2 | G6: #2, Passing Chris Chiozza (1)
A7: Tyson Etienne | B7: LIN | C7: Double-Doubles | D7: ='Tyson Etienne'!B23 -> 0 | E7: =F7-D7 -> 2 | F7: 2 | G7: #2, Passing Chris Chiozza (1)
A8: Malachi Smith | B8: LIN | C8: Double-Doubles | D8: ='Malachi Smith'!B23 -> 0 | E8: =F8-D8 -> 2 | F8: 2 | G8: #2, Passing Chris Chiozza (1)
A9: Mfon Udofia | B9: LIN | C9: Wins | D9: ='Mfon Udofia'!C6 -> 2 | E9: =F9-D9 -> 2 | F9: 4 | G9: #1, Passing Will Weaver (3)
A10: David Muoka | B10: LIN | C10: Games Played | D10: ='David Muoka'!B26 -> 4 | E10: =F10-D10 -> 2 | F10: 6 | G10: #1, Passing Tahjere McCall (5)
A11: David Muoka | B11: LIN | C11: Rebounds | D11: ='David Muoka'!B17 -> 27 | E11: =F11-D11 -> 6 | F11: 33 | G11: #2, Passing Thomas Wimbush (32)
A12: David Muoka | B12: LIN | C12: Blocks | D12: ='David Muoka'!B20 -> 7 | E12: =F12-D12 -> 8 | F12: 15 | G12: #1, Passing Alan Williams (14)
A13: Malachi Smith | B13: LIN | C13: Steals | D13: ='Malachi Smith'!B19 -> 2 | E13: =F13-D13 -> 9 | F13: 11 | G13: #2, Passing Jordan McLaughlin (10)
A14: Tyson Etienne | B14: LIN | C14: Steals | D14: ='Tyson Etienne'!B19 -> 1 | E14: =F14-D14 -> 10 | F14: 11 | G14: #2, Passing Jordan McLaughlin (10)
A15: Chaney Johnson | B15: LIN | C15: Steals | D15: ='Chaney Johnson'!B19 -> 1 | E15: =F15-D15 -> 10 | F15: 11 | G15: #2, Passing Jordan McLaughlin (10)
A16: Trevon Scott | B16: LIN | C16: Steals | D16: ='Trevon Scott'!D19 -> 0 | E16: =F16-D16 -> 11 | F16: 11 | G16: #2, Passing Jordan McLaughlin (10)
A17: Yuri Collins | B17: Career | C17: Rebounds | D17: ='Yuri Collins'!B3 -> 332 | E17: =F17-D17 -> 18 | F17: 350
A18: Terry Roberts | B18: LIN | C18: Steals | D18: ='Terry Roberts'!B19 -> 0 | E18: =F18-D18 -> 11 | F18: 11 | G18: #2, Passing Jordan McLaughlin (10)
A19: Yuri Collins | B19: Career | C19: Steals | D19: ='Yuri Collins'!B5 -> 126 | E19: =F19-D19 -> 24 | F19: 150
A20: E.J. Liddell | B20: LIN | C20: Steals | D20: ='E.J. Liddell'!B19 -> 0 | E20: =F20-D20 -> 11 | F20: 11 | G20: #2, Passing Jordan McLaughlin (10)
A21: Malachi Smith | B21: LIN | C21: 3PM | D21: ='Malachi Smith'!B22 -> 3 | E21: =F21-D21 -> 11 | F21: 14 | G21: #1, Passing Jacob Gilyard (13)
A22: Malachi Smith | B22: LIN | C22: Assists | D22: ='Malachi Smith'!B18 -> 4 | E22: =F22-D22 -> 11 | F22: 15 | G22: #1, Passing Jacob Gilyard (13)
A23: Tyson Etienne | B23: LIN | C23: 3PM | D23: ='Tyson Etienne'!B22 -> 2 | E23: =F23-D23 -> 12 | F23: 14 | G23: #1, Passing Jacob Gilyard (13)
A24: E.J. Liddell | B24: LIN | C24: Blocks | D24: ='E.J. Liddell'!B20 -> 3 | E24: =F24-D24 -> 12 | F24: 15 | G24: #1, Passing Alan Williams (14)
A25: Hunter Cattoor | B25: LIN | C25: 3PM | D25: ='Hunter Cattoor'!B22 -> 0 | E25: =F25-D25 -> 14 | F25: 14 | G25: #1, Passing Jacob Gilyard (13)
A26: Chaney Johnson | B26: LIN | C26: Blocks | D26: ='Chaney Johnson'!B20 -> 1 | E26: =F26-D26 -> 14 | F26: 15 | G26: #1, Passing Alan Williams (14)
A27: Terry Roberts | B27: LIN | C27: Assists | D27: ='Terry Roberts'!B18 -> 0 | E27: =F27-D27 -> 15 | F27: 15 | G27: #5, Passing Keon Johnson (14)
A28: Tyson Etienne | B28: LIN | C28: Assists | D28: ='Tyson Etienne'!B18 -> 0 | E28: =F28-D28 -> 15 | F28: 15 | G28: #5, Passing Keon Johnson (14)
A29: E.J. Liddell | B29: LIN | C29: Rebounds | D29: ='E.J. Liddell'!B17 -> 9 | E29: =F29-D29 -> 24 | F29: 33 | G29: #2, Passing Thomas Wimbush (32)
A30: Alex Schumacher | B30: Career | C30: Points | D30: ='Alex Schumacher'!B16 -> 23 | E30: =F30-D30 -> 27 | F30: 50
A31: Malachi Smith | B31: LIN | C31: Rebounds | D31: ='Malachi Smith'!B17 -> 6 | E31: =F31-D31 -> 27 | F31: 33 | G31: #2, Passing Thomas Wimbush (32)
A32: Chaney Johnson | B32: LIN | C32: Rebounds | D32: ='Chaney Johnson'!B17 -> 6 | E32: =F32-D32 -> 27 | F32: 33 | G32: #2, Passing Thomas Wimbush (32)
A33: E.J. Liddell | B33: LIN | C33: Points | D33: ='E.J. Liddell'!B16 -> 32 | E33: =F33-D33 -> 28 | F33: 60 | G33: #7, Passing Keon Johnson (59)
A34: Trevon Scott | B34: LIN | C34: Rebounds | D34: ='Trevon Scott'!D17 -> 3 | E34: =F34-D34 -> 30 | F34: 33 | G34: #2, Passing Thomas Wimbush (32)
A35: David Muoka | B35: LIN | C35: Points | D35: ='David Muoka'!B16 -> 30 | E35: =F35-D35 -> 30 | F35: 60 | G35: #7, Passing Keon Johnson (59)
A36: Trevon Scott | B36: Career | C36: Points | D36: ='Trevon Scott'!B16 -> 12 | E36: =F36-D36 -> 38 | F36: 50
A37: Chaney Johnson | B37: LIN | C37: Points | D37: ='Chaney Johnson'!B16 -> 22 | E37: =F37-D37 -> 38 | F37: 60 | G37: #7, Passing Keon Johnson (59)
A38: Trevon Scott | B38: Career | C38: Rebounds | D38: ='Trevon Scott'!B17 -> 11 | E38: =F38-D38 -> 39 | F38: 50
A39: Alex Schumacher | B39: Career | C39: Rebounds | D39: ='Alex Schumacher'!B17 -> 10 | E39: =F39-D39 -> 40 | F39: 50
A40: Alex Schumacher | B40: Career | C40: Assists | D40: ='Alex Schumacher'!B18 -> 7 | E40: =F40-D40 -> 43 | F40: 50
...

Sheet Mfon Udofia
A1: MFON UDOFIA | B1: PRE 3/10/26 | C1: CURRENT | D1: 46096 | E1: 46098 | F1: 46100 | G1: 46103 | H1: 46105 | I1: 46106 | J1: 46109
A2: WINS | B2: 72 | C2: =SUM(B2,D2:J2) -> 72 | D2: 0 | E2: 0 | F2: 0 | G2: 0 | H2: 0 | I2: 0 | J2: 0
A3: GAMES | B3: =(71+B2) -> 143 | C3: =SUM(B3,D3:J3) -> 150 | D3: 1 | E3: 1 | F3: 1 | G3: 1 | H3: 1 | I3: 1 | J3: 1
A5: PLAYOFFS: | B5: Pre 2026 | C5: CURRENT | D5: 46113
A6: WINS | B6: 2 | C6: =SUM(B6,D6:J6) -> 2 | D6: 0
A7: GAMES | B7: 3 | C7: =SUM(B7,D7:J7) -> 4 | D7: 1

Sheet Hunter Cattoor
A1: HUNTER CATTOOR | B1: All-Time | C1: 2025-26 | D1: 45968 | E1: 45970 | F1: 45975 | G1: 45976 | H1: 45983 | I1: 45985 | J1: 45987 | K1: 45990 | L1: 45992 | M1: 45996 | N1: 45997 | O1: 46000 | P1: 46001 | Q1: 46003 | R1: 46011 | S1: 46013 | T1: 46019 | U1: 45659 | V1: 45661 | W1: 45663 | X1: 45665 | Y1: 45666 | Z1: 45669 | AA1: 45671 | AB1: 46040 | AC1: 46041 | AD1: 46043 | AE1: 46045 | AF1: 46048 | AG1: 46050 | AH1: 46055 | AI1: 46058 | AJ1: 46059 | AK1: 46061 | AL1: 46063 | AM1: 46065 | AN1: 46072 | AO1: 46073 | AP1: 46078 | AQ1: 46079 | AR1: 46082 | AS1: 46085 | AT1: 46087 | AU1: 46096 | AV1: 46098 | AW1: 46100 | AX1: 46103 | AY1: 46105 | AZ1: 46106 | BA1: 46109
A2: Points | B2: =SUM(D2:BA2) -> 287 | C2: =+SUM(D2:AY2) -> 244 | D2: 9 | E2: 8 | F2: 0 | J2: 14 | K2: 5 | L2: 12 | P2: 2 | Q2: 9 | S2: 0 | T2: 3 | U2: 6 | W2: 12 | X2: 3 | Y2: 8 | Z2: 8 | AA2: 8 | AB2: 0 | AI2: 0 | AJ2: 5 | AK2: 2 | AL2: 6 | AM2: 12 | AN2: 8 | AO2: 12 | AP2: 2 | AQ2: 3 | AR2: 5 | AS2: 3 | AT2: 6 | AU2: 20 | AV2: 7 | AX2: 21 | AY2: 25 | AZ2: 28 | BA2: 15
A3: Rebounds | B3: =+SUM(D3:BA3) -> 64 | C3: =+SUM(D3:BA3) -> 64 | D3: 4 | E3: 3 | F3: 0 | J3: 3 | K3: 0 | L3: 2 | P3: 1 | Q3: 4 | S3: 0 | T3: 0 | U3: 4 | W3: 2 | X3: 3 | Y3: 3 | Z3: 3 | AA3: 4 | AB3: 0 | AI3: 0 | AJ3: 1 | AK3: 1 | AL3: 1 | AM3: 4 | AN3: 0 | AO3: 2 | AP3: 0 | AQ3: 0 | AR3: 0 | AS3: 0 | AT3: 0 | AU3: 2 | AV3: 1 | AX3: 6 | AY3: 3 | AZ3: 4 | BA3: 3
A4: Assists | B4: =+SUM(D4:BA4) -> 43 | C4: =+SUM(D4:BA4) -> 43 | D4: 1 | E4: 1 | F4: 1 | J4: 4 | K4: 2 | L4: 2 | P4: 1 | Q4: 2 | S4: 0 | T4: 2 | U4: 0 | W4: 1 | X4: 1 | Y4: 2 | Z4: 1 | AA4: 0 | AB4: 0 | AI4: 0 | AJ4: 2 | AK4: 0 | AL4: 1 | AM4: 1 | AN4: 2 | AO4: 0 | AP4: 1 | AQ4: 2 | AR4: 1 | AS4: 0 | AT4: 0 | AU4: 1 | AV4: 0 | AX4: 4 | AY4: 3 | AZ4: 2 | BA4: 2
A5: Steals | B5: =+SUM(D5:BA5) -> 30 | C5: =+SUM(D5:BA5) -> 30 | D5: 0 | E5: 0 | F5: 1 | J5: 1 | K5: 0 | L5: 2 | P5: 2 | Q5: 0 | S5: 2 | T5: 1 | U5: 0 | W5: 0 | X5: 0 | Y5: 1 | Z5: 1 | AA5: 0 | AB5: 0 | AI5: 0 | AJ5: 1 | AK5: 0 | AL5: 0 | AM5: 1 | AN5: 0 | AO5: 1 | AP5: 1 | AQ5: 0 | AR5: 1 | AS5: 3 | AT5: 0 | AU5: 1 | AV5: 1 | AX5: 3 | AY5: 3 | AZ5: 2 | BA5: 1
A6: Blocks | B6: =+SUM(D6:BA6) -> 1 | C6: =+SUM(B6:D6) -> 0 | D6: 0 | E6: 0 | F6: 0 | J6: 0 | K6: 0 | L6: 0 | P6: 0 | Q6: 0 | S6: 0 | T6: 0 | U6: 0 | W6: 0 | X6: 0 | Y6: 0 | Z6: 0 | AA6: 0 | AB6: 0 | AI6: 0 | AJ6: 0 | AK6: 0 | AL6: 0 | AM6: 0 | AN6: 0 | AO6: 0 | AP6: 0 | AQ6: 0 | AR6: 0 | AS6: 0 | AT6: 0 | AU6: 0 | AV6: 0 | AX6: 0 | AY6: 1 | AZ6: 0 | BA6: 0
A7: FGM | B7: =+SUM(D7:BA7) -> 89 | C7: =+SUM(D7:BA7) -> 89 | D7: 2 | E7: 2 | F7: 0 | J7: 4 | K7: 1 | L7: 4 | P7: 1 | Q7: 3 | S7: 0 | T7: 1 | U7: 2 | W7: 4 | X7: 1 | Y7: 2 | Z7: 1 | AA7: 2 | AB7: 0 | AI7: 0 | AJ7: 1 | AK7: 0 | AL7: 2 | AM7: 3 | AN7: 3 | AO7: 4 | AP7: 1 | AQ7: 1 | AR7: 1 | AS7: 1 | AT7: 1 | AU7: 6 | AV7: 3 | AX7: 8 | AY7: 8 | AZ7: 11 | BA7: 5
A8: 3PM | B8: =+SUM(D8:BA8) -> 68 | C8: =+SUM(D8:BA8) -> 68 | D8: 2 | E8: 2 | F8: 0 | J8: 3 | K8: 1 | L8: 4 | P8: 0 | Q8: 3 | S8: 0 | T8: 1 | U8: 2 | W8: 4 | X8: 1 | Y8: 2 | Z8: 0 | AA8: 2 | AB8: 0 | AI8: 0 | AJ8: 1 | AK8: 0 | AL8: 2 | AM8: 3 | AN8: 2 | AO8: 4 | AP8: 0 | AQ8: 1 | AR8: 1 | AS8: 1 | AT8: 1 | AU8: 4 | AV8: 1 | AX8: 5 | AY8: 5 | AZ8: 6 | BA8: 4
A9: Double Doubles | B9: =+SUM(D9:BA9) -> 0 | C9: =+SUM(B9:BA9) -> 0 | D9: 0 | E9: 0 | F9: 0 | J9: 0 | K9: 0 | L9: 0 | P9: 0 | Q9: 0 | S9: 0 | T9: 0 | U9: 0 | W9: 0 | X9: 0 | Y9: 0 | Z9: 0 | AA9: 0 | AB9: 0 | AI9: 0 | AJ9: 0 | AK9: 0 | AL9: 0 | AM9: 0 | AN9: 0 | AO9: 0 | AP9: 0 | AQ9: 0 | AR9: 0 | AS9: 0 | AT9: 0 | AU9: 0 | AV9: 0 | AX9: 0 | AY9: 0 | AZ9: 0 | BA9: 0
A10: MIN | B10: =+SUM(D10:BA10) -> 636.42667 | C10: =+SUM(D10:BA10) -> 636.42667 | D10: =22+(8/60) -> 22.133333 | E10: =22+(23/60) -> 22.383333 | F10: 14.59 | J10: 23.29 | K10: 17.00 | L10: 19.22 | P10: 12.17 | Q10: 22.58 | S10: 11.55 | T10: 16.05 | U10: 26.24 | W10: 19.15 | X10: 21.15 | Y10: 22.47 | Z10: 20.16 | AA10: 23.53 | AB10: 10.35 | AI10: 2.3 | AJ10: 19.09 | AK10: 6.54 | AL10: 10.1 | AM10: 20.06 | AN10: 9.12 | AO10: 13.41 | AP10: 11.51 | AQ10: 18.36 | AR10: 16.07 | AS10: 13.29 | AT10: 17.21 | AU10: 41.26 | AV10: 18.25 | AX10: 38.21 | AY10: 35.53 | AZ10: 27.29 | BA10: 26.4
A11: FTM | B11: =+SUM(D11:BA11) -> 21 | C11: =SUM(D11:BA11) -> 21 | D11: 1 | E11: 1 | F11: 0 | J11: 1 | K11: 1 | L11: 0 | P11: 0 | Q11: 0 | S11: 0 | T11: 0 | U11: 0 | W11: 0 | X11: 0 | Y11: 1 | Z11: 3 | AA11: 2 | AB11: 0 | AI11: 0 | AJ11: 1 | AK11: 1 | AL11: 0 | AM11: 1 | AN11: 0 | AO11: 0 | AP11: 0 | AQ11: 0 | AR11: 0 | AS11: 0 | AT11: 2 | AU11: 3 | AV11: 0 | AX11: 0 | AY11: 2 | AZ11: 0 | BA11: 1
A12: GP | B12: =+SUM(D12:BA12) -> 35 | C12: =SUM(B12:BA12) -> 0 | D12: 1 | E12: 1 | F12: 1 | J12: 1 | K12: 1 | L12: 1 | P12: 1 | Q12: 1 | S12: 1 | T12: 1 | U12: 1 | W12: 1 | X12: 1 | Y12: 1 | Z12: 1 | AA12: 1 | AB12: 1 | AI12: 1 | AJ12: 1 | AK12: 1 | AL12: 1 | AM12: 1 | AN12: 1 | AO12: 1 | AP12: 1 | AQ12: 1 | AR12: 1 | AS12: 1 | AT12: 1 | AU12: 1 | AV12: 1 | AX12: 1 | AY12: 1 | AZ12: 1 | BA12: 1
A15: PLAYOFFS: | B15: All-Time | C15: 2025-26 | D15: 46113
A16: Points | B16: =SUM(D16:BA16) -> 5 | C16: 5 | D16: 5
A17: Rebounds | B17: =SUM(D17:BA17) -> 3 | C17: 3 | D17: 3
A18: Assists | B18: =SUM(D18:BA18) -> 3 | C18: 3 | D18: 3
A19: Steals | B19: =SUM(D19:BA19) -> 0 | C19: 0 | D19: 0
A20: Blocks | B20: =SUM(D20:BA20) -> 0 | C20: 0 | D20: 0
A21: FGM | B21: =SUM(D21:BA21) -> 0 | C21: 0 | D21: 0
A22: 3PM | B22: =SUM(D22:BA22) -> 0 | C22: 0 | D22: 0
A23: Double Doubles | B23: =SUM(D23:BA23) -> 0 | C23: 0 | D23: 0
A24: MIN | B24: =SUM(D24:BA24) -> 25.36 | C24: 25.36 | D24: 25.36
A25: FTM | B25: =SUM(D25:BA25) -> 2 | C25: 2 | D25: 2
A26: GP | B26: =SUM(D26:BA26) -> 1 | C26: 1 | D26: 1

Sheet Yuri Collins
A1: YURI COLLINS | B1: All-Time | C1: Pre 2025 | D1: LIN | E1: 2025-26 | F1: 45968 | G1: 45970 | H1: 45975 | I1: 45976 | J1: 45983 | K1: 45985 | L1: 45987 | M1: 45990 | N1: 45992 | O1: 45996 | P1: 45997 | Q1: 46000 | R1: 46001 | S1: 46003 | T1: 46011 | U1: 46013
A2: Points | B2: =C2+SUM(F2:AI2) -> 1099 | C2: 944 | D2: =+SUM(F2:AI2) -> 155 | E2: =+SUM(F2:AI2) -> 155 | F2: 8 | G2: 8 | H2: 12 | I2: 11 | J2: 16 | K2: 24 | L2: 8 | M2: 4 | N2: 11 | O2: 4 | P2: 10 | Q2: 4 | R2: 13 | S2: 9 | T2: 13 | U2: 0
A3: Rebounds | B3: =C3+SUM(F3:AI3) -> 332 | C3: 284 | D3: =SUM(F3:AI3) -> 48 | E3: =SUM(F3:AI3) -> 48 | F3: 2 | G3: 3 | H3: 5 | I3: 3 | J3: 6 | K3: 2 | L3: 2 | M3: 1 | N3: 1 | O3: 3 | P3: 1 | Q3: 5 | R3: 6 | S3: 2 | T3: 2 | U3: 4
A4: Assists | B4: =C4+SUM(F4:AI4) -> 841 | C4: 737 | D4: =SUM(F4:AI4) -> 104 | E4: =SUM(F4:AI4) -> 104 | F4: 4 | G4: 6 | H4: 4 | I4: 10 | J4: 8 | K4: 6 | L4: 5 | M4: 5 | N4: 8 | O4: 8 | P4: 10 | Q4: 3 | R4: 6 | S4: 10 | T4: 5 | U4: 6
A5: Steals | B5: =C5+SUM(F5:AI5) -> 126 | C5: 102 | D5: =SUM(F5:AI5) -> 24 | E5: =SUM(F5:AI5) -> 24 | F5: 1 | G5: 1 | H5: 1 | I5: 4 | J5: 3 | K5: 1 | L5: 2 | M5: 2 | N5: 0 | O5: 1 | P5: 0 | Q5: 1 | R5: 2 | S5: 2 | T5: 1 | U5: 2
A6: Blocks | B6: =C6+SUM(F6:AI6) -> 26 | C6: 19 | D6: =SUM(F6:AI6) -> 7 | E6: =SUM(F6:AI6) -> 7 | F6: 0 | G6: 0 | H6: 0 | I6: 0 | J6: 2 | K6: 2 | L6: 1 | M6: 0 | N6: 0 | O6: 0 | P6: 1 | Q6: 0 | R6: 0 | S6: 0 | T6: 0 | U6: 1
A7: FGM | B7: =C7+SUM(F7:AI7) -> 413 | C7: 358 | D7: =SUM(F7:AI7) -> 55 | E7: =SUM(F7:AI7) -> 55 | F7: 4 | G7: 3 | H7: 3 | I7: 3 | J7: 4 | K7: 9 | L7: 1 | M7: 1 | N7: 4 | O7: 2 | P7: 4 | Q7: 2 | R7: 6 | S7: 4 | T7: 5 | U7: 0
A8: 3PM | B8: =C8+SUM(F8:AI8) -> 86 | C8: 72 | D8: =SUM(F8:AI8) -> 14 | E8: =SUM(F8:AI8) -> 14 | F8: 0 | G8: 2 | H8: 0 | I8: 1 | J8: 3 | K8: 2 | L8: 0 | M8: 0 | N8: 1 | O8: 0 | P8: 1 | Q8: 0 | R8: 1 | S8: 0 | T8: 3 | U8: 0
A9: Double Doubles | B9: =C9+SUM(F9:AI9) -> 25 | C9: 23 | D9: =SUM(F9:AI9) -> 2 | E9: =SUM(F9:AI9) -> 2 | F9: 0 | G9: 0 | H9: 0 | I9: 1 | J9: 0 | K9: 0 | L9: 0 | M9: 0 | N9: 0 | O9: 0 | P9: 1 | Q9: 0 | R9: 0 | S9: 0 | T9: 0 | U9: 0
A10: MIN | B10: =C10+SUM(F10:AI10) -> 3134.83 | C10: 2732.2 | D10: =SUM(F10:AI10) -> 402.63 | F10: 29.35 | G10: 35.14 | H10: 31.53 | I10: 37.37 | J10: 36.15 | K10: 39.03 | L10: 26.38 | M10: 26.45 | N10: 25.3 | O10: 35.19 | P10: 30 | Q10: 28.42 | R10: 32.49 | S10: 33.59 | T10: 27.14 | U10: 25.12
A11: FTM | B11: =C11+SUM(F11:AI11) -> 118 | C11: 101 | D11: =SUM(F11:AI11) -> 17 | E11: =SUM(F11:AI11) -> 17 | F11: 0 | G11: 0 | H11: 3 | I11: 2 | J11: 3 | K11: 2 | L11: 3 | M11: 1 | N11: 1 | O11: 0 | P11: 1 | Q11: 0 | R11: 0 | S11: 1 | T11: 0 | U11: 0
A12: GP | B12: =C12+SUM(F12:AI12) -> 115 | C12: 99 | D12: =SUM(F12:AI12) -> 16 | E12: =SUM(F12:AI12) -> 16 | F12: 1 | G12: 1 | H12: 1 | I12: 1 | J12: 1 | K12: 1 | L12: 1 | M12: 1 | N12: 1 | O12: 1 | P12: 1 | Q12: 1 | R12: 1 | S12: 1 | T12: 1 | U12: 1

Sheet D'Andre Davis
A1: D'ANDRE DAVIS | B1: All-Time | C1: 2025-26 | D1: 45968 | E1: 45970 | F1: 45975 | G1: 45976 | H1: 45983 | I1: 45985 | J1: 45987 | K1: 45990 | L1: 45992 | M1: 45996 | N1: 45997 | O1: 46000 | P1: 46001 | Q1: 46003 | R1: 46011 | S1: 46013 | T1: 46019 | U1: 45659 | V1: 45661 | W1: 45663 | X1: 45665 | Y1: 45666 | Z1: 45669 | AA1: 45671 | AB1: 46040 | AC1: 46041 | AD1: 46043 | AE1: 46045 | AF1: 46048 | AG1: 46050 | AH1: 46055 | AI1: 46058 | AJ1: 46059 | AK1: 46061 | AL1: 46063 | AM1: 46065 | AN1: 46072 | AO1: 46073 | AP1: 46078 | AQ1: 46079 | AR1: 46082 | AS1: 46085 | AT1: 46087 | AU1: 46096 | AV1: 46098 | AW1: 46100 | AX1: 46103 | AY1: 46105 | AZ1: 46106 | BA1: 46109
A2: Points | B2: =+SUM(D2:BA2) -> 263 | C2: =+SUM(D2:BA2) -> 263 | D2: 2 | F2: 2 | H2: 0 | I2: 5 | K2: 10 | L2: 7 | M2: 10 | N2: 0 | O2: 0 | P2: 9 | Q2: 15 | R2: 6 | S2: 4 | T2: 5 | U2: 7 | V2: 0 | W2: 9 | X2: 0 | Y2: 14 | Z2: 7 | AA2: 0 | AC2: 0 | AD2: 6 | AE2: 0 | AF2: 2 | AI2: 0 | AK2: 0 | AR2: 4 | AS2: 2 | AT2: 5 | AU2: 25 | AV2: 20 | AW2: 17 | AX2: 15 | AY2: 24 | AZ2: 15 | BA2: 16
A3: Rebounds | B3: =+SUM(D3:BA3) -> 96 | C3: =SUM(D3:BA3) -> 96 | D3: 2 | F3: 1 | H3: 0 | I3: 0 | K3: 2 | L3: 1 | M3: 2 | N3: 0 | O3: 2 | P3: 4 | Q3: 4 | R3: 4 | S3: 1 | T3: 2 | U3: 2 | V3: 0 | W3: 3 | X3: 1 | Y3: 3 | Z3: 3 | AA3: 2 | AC3: 0 | AD3: 3 | AE3: 1 | AF3: 0 | AI3: 0 | AK3: 2 | AR3: 3 | AS3: 1 | AT3: 6 | AU3: 5 | AV3: 8 | AW3: 7 | AX3: 4 | AY3: 7 | AZ3: 2 | BA3: 8
A4: Assists | B4: =+SUM(D4:BA4) -> 33 | C4: =SUM(B4:D4) -> 0 | D4: 0 | F4: 0 | H4: 1 | I4: 0 | K4: 0 | L4: 1 | M4: 2 | N4: 0 | O4: 0 | P4: 0 | Q4: 2 | R4: 0 | S4: 0 | T4: 0 | U4: 0 | V4: 0 | W4: 3 | X4: 0 | Y4: 0 | Z4: 0 | AA4: 0 | AC4: 0 | AD4: 0 | AE4: 0 | AF4: 0 | AI4: 1 | AK4: 0 | AR4: 2 | AS4: 0 | AT4: 3 | AU4: 1 | AV4: 2 | AW4: 3 | AX4: 4 | AY4: 4 | AZ4: 2 | BA4: 2
A5: Steals | B5: =+SUM(D5:BA5) -> 22 | C5: =SUM(B5:D5) -> 0 | D5: 1 | F5: 0 | H5: 0 | I5: 0 | K5: 0 | L5: 1 | M5: 0 | N5: 0 | O5: 0 | P5: 0 | Q5: 1 | R5: 2 | S5: 1 | T5: 0 | U5: 1 | V5: 1 | W5: 1 | X5: 0 | Y5: 1 | Z5: 1 | AA5: 0 | AC5: 0 | AD5: 0 | AE5: 0 | AF5: 0 | AI5: 0 | AK5: 0 | AR5: 1 | AS5: 0 | AT5: 0 | AU5: 1 | AV5: 1 | AW5: 1 | AX5: 2 | AY5: 3 | AZ5: 1 | BA5: 1
A6: Blocks | B6: =+SUM(D6:BA6) -> 16 | C6: =SUM(B6:D6) -> 0 | D6: 0 | F6: 1 | H6: 0 | I6: 0 | K6: 1 | L6: 1 | M6: 0 | N6: 0 | O6: 0 | P6: 0 | Q6: 1 | R6: 0 | S6: 0 | T6: 1 | U6: 0 | V6: 0 | W6: 0 | X6: 1 | Y6: 1 | Z6: 0 | AA6: 1 | AC6: 0 | AD6: 0 | AE6: 0 | AF6: 0 | AI6: 0 | AK6: 0 | AR6: 1 | AS6: 0 | AT6: 0 | AU6: 1 | AV6: 1 | AW6: 3 | AX6: 1 | AY6: 1 | AZ6: 0 | BA6: 0
A7: FGM | B7: =+SUM(D7:BA7) -> 92 | C7: =SUM(D7:BA7) -> 92 | D7: 0 | F7: 1 | H7: 0 | I7: 1 | K7: 4 | L7: 3 | M7: 3 | N7: 0 | O7: 0 | P7: 4 | Q7: 5 | R7: 2 | S7: 1 | T7: 2 | U7: 1 | V7: 0 | W7: 2 | X7: 0 | Y7: 5 | Z7: 3 | AA7: 0 | AC7: 0 | AD7: 3 | AE7: 0 | AF7: 0 | AI7: 0 | AK7: 0 | AR7: 2 | AS7: 0 | AT7: 2 | AU7: 7 | AV7: 7 | AW7: 5 | AX7: 6 | AY7: 10 | AZ7: 7 | BA7: 6
A8: 3PM | B8: =+SUM(D8:BA8) -> 19 | C8: =SUM(B8:D8) -> 0 | D8: 0 | F8: 0 | H8: 0 | I8: 0 | K8: 0 | L8: 1 | M8: 1 | N8: 0 | O8: 0 | P8: 1 | Q8: 1 | R8: 2 | S8: 0 | T8: 1 | U8: 1 | V8: 0 | W8: 1 | X8: 0 | Y8: 1 | Z8: 0 | AA8: 0 | AC8: 0 | AD8: 0 | AE8: 0 | AF8: 0 | AI8: 0 | AK8: 0 | AR8: 0 | AS8: 0 | AT8: 1 | AU8: 3 | AV8: 0 | AW8: 1 | AX8: 0 | AY8: 1 | AZ8: 1 | BA8: 2
A9: Double Doubles | B9: =+SUM(B9:D9) -> 0 | C9: =SUM(D9:BA9) -> 0 | D9: 0 | F9: 0 | H9: 0 | I9: 0 | K9: 0 | L9: 0 | M9: 0 | N9: 0 | O9: 0 | P9: 0 | Q9: 0 | R9: 0 | S9: 0 | T9: 0 | U9: 0 | V9: 0 | W9: 0 | X9: 0 | Y9: 0 | Z9: 0 | AA9: 0 | AC9: 0 | AD9: 0 | AE9: 0 | AF9: 0 | AI9: 0 | AK9: 0 | AR9: 0 | AS9: 0 | AT9: 0 | AU9: 0 | AV9: 0 | AW9: 0 | AX9: 0 | AY9: 0 | AZ9: 0 | BA9: 0
A10: MIN | B10: =+SUM(D10:BA10) -> 561.45 | C10: =SUM(D10:BA10) -> 561.45 | D10: 8.05 | F10: 15.05 | H10: 3.29 | I10: 9.12 | K10: 15.3 | L10: 12.54 | M10: 17.12 | N10: 6.43 | O10: 5.19 | P10: 16.05 | Q10: 22.18 | R10: 12.28 | S10: 12.28 | T10: 13.01 | U10: 8.53 | V10: 7.24 | W10: 19.59 | X10: 13.34 | Y10: 18.19 | Z10: 23.59 | AA10: 23.53 | AC10: 11.18 | AD10: 16.51 | AE10: 3.59 | AF10: 4.07 | AI10: 5.14 | AK10: 2.44 | AR10: 10.14 | AS10: 10.19 | AT10: 15.41 | AU10: 29.38 | AV10: 38.45 | AW10: 33.03 | AX10: 39.14 | AY10: 32.47 | AZ10: 25.47 | BA10: 26.04
A11: FTM | B11: =+SUM(D11:BA11) -> 36 | C11: =SUM(D11:BA11) -> 36 | D11: 1 | F11: 0 | H11: 0 | I11: 1 | K11: 1 | L11: 0 | M11: 2 | N11: 0 | O11: 0 | P11: 0 | Q11: 3 | R11: 0 | S11: 1 | T11: 0 | U11: 2 | V11: 0 | W11: 2 | X11: 0 | Y11: 2 | Z11: 1 | AA11: 2 | AC11: 0 | AD11: 0 | AE11: 0 | AF11: 1 | AI11: 0 | AK11: 0 | AR11: 0 | AS11: 1 | AT11: 0 | AU11: 4 | AV11: 3 | AW11: 4 | AX11: 2 | AY11: 2 | AZ11: 0 | BA11: 1
A12: GP | B12: =+SUM(D12:BA12) -> 37 | C12: =SUM(D12:BA12) -> 37 | D12: 1 | F12: 1 | H12: 1 | I12: 1 | K12: 1 | L12: 1 | M12: 1 | N12: 1 | O12: 1 | P12: 1 | Q12: 1 | R12: 1 | S12: 1 | T12: 1 | U12: 1 | V12: 1 | W12: 1 | X12: 1 | Y12: 1 | Z12: 1 | AA12: 1 | AC12: 1 | AD12: 1 | AE12: 1 | AF12: 1 | AI12: 1 | AK12: 1 | AR12: 1 | AS12: 1 | AT12: 1 | AU12: 1 | AV12: 1 | AW12: 1 | AX12: 1 | AY12: 1 | AZ12: 1 | BA12: 1
A15: PLAYOFFS: | B15: All-Time | C15: 2025-26 | D15: 46113
A16: Points | B16: =SUM(D16:BA16) -> 8 | C16: 8 | D16: 8
A17: Rebounds | B17: =SUM(D17:BA17) -> 5 | C17: 5 | D17: 5
A18: Assists | B18: =SUM(D18:BA18) -> 2 | C18: 2 | D18: 2
A19: Steals | B19: =SUM(D19:BA19) -> 1 | C19: 1 | D19: 1
A20: Blocks | B20: =SUM(D20:BA20) -> 0 | C20: 0 | D20: 0
A21: FGM | B21: =SUM(D21:BA21) -> 3 | C21: 3 | D21: 3
A22: 3PM | B22: =SUM(D22:BA22) -> 2 | C22: 2 | D22: 2
A23: Double Doubles | B23: =SUM(D23:BA23) -> 0 | C23: 0 | D23: 0
A24: MIN | B24: =SUM(D24:BA24) -> 24.32 | C24: 24.32 | D24: 24.32
A25: FTM | B25: =SUM(D25:BA25) -> 0 | C25: 0 | D25: 0
A26: GP | B26: =SUM(D26:BA26) -> 1 | C26: 1 | D26: 1

Sheet Tyson Etienne
A1: TYSON ETIENNE | B1: All-Time | C1: Pre 2025 | D1: 2024-25 (LIN) | E1: LIN | F1: 2025-26 | G1: 45996 | H1: 45997 | I1: 46000 | J1: 46001 | K1: 46003 | L1: 46011 | M1: 46013 | N1: 46019 | O1: 45659 | P1: 45661 | Q1: 45663 | R1: 45665 | S1: 45666 | T1: 45669 | U1: 46040 | V1: 46041 | W1: 46043 | X1: 46045 | Y1: 46048 | Z1: 46050 | AA1: 46055 | AB1: 46058 | AC1: 46059 | AD1: 46061 | AE1: 46063 | AF1: 46065 | AG1: 46072 | AH1: 46073 | AI1: 46078 | AJ1: 46079 | AK1: 46082 | AL1: 46085 | AM1: 46087
A2: Points | B2: =C2+SUM(G2:AZ2) -> 2042 | C2: 1521 | D2: 822 | E2: =D2+SUM(G2:AZ2) -> 1343 | F2: =SUM(G2:AZ2) -> 521 | G2: 14 | H2: 34 | I2: 14 | J2: 13 | K2: 20 | L2: 11 | M2: 13 | N2: 18 | O2: 35 | P2: 22 | Q2: 16 | R2: 22 | S2: 12 | U2: 27 | V2: 16 | W2: 15 | X2: 2 | Y2: 22 | Z2: 15 | AA2: 26 | AB2: 5 | AC2: 15 | AD2: 12 | AE2: 23 | AF2: 8 | AG2: 14 | AH2: 10 | AI2: 12 | AJ2: 18 | AK2: 14 | AL2: 11 | AM2: 12
A3: Rebounds | B3: =C3+SUM(G3:AZ3) -> 404 | C3: 312 | D3: 148 | E3: =D3+SUM(G3:AZ3) -> 240 | F3: =SUM(G3:AZ3) -> 92 | G3: 5 | H3: 4 | I3: 1 | J3: 0 | K3: 1 | L3: 2 | M3: 2 | N3: 5 | O3: 6 | P3: 2 | Q3: 5 | R3: 4 | S3: 3 | U3: 3 | V3: 2 | W3: 1 | X3: 3 | Y3: 4 | Z3: 1 | AA3: 4 | AB3: 1 | AC3: 1 | AD3: 2 | AE3: 6 | AF3: 4 | AG3: 3 | AH3: 4 | AI3: 1 | AJ3: 6 | AK3: 1 | AL3: 3 | AM3: 2
A4: Assists | B4: =C4+SUM(G4:AZ4) -> 507 | C4: 381 | D4: 168 | E4: =D4+SUM(G4:AZ4) -> 294 | F4: =SUM(G4:AZ4) -> 126 | G4: 2 | H4: 4 | I4: 2 | J4: 1 | K4: 2 | L4: 6 | M4: 1 | N4: 3 | O4: 2 | P4: 6 | Q4: 8 | R4: 3 | S4: 6 | U4: 4 | V4: 10 | W4: 8 | X4: 2 | Y4: 7 | Z4: 2 | AA4: 6 | AB4: 3 | AC4: 0 | AD4: 4 | AE4: 4 | AF4: 5 | AG4: 5 | AH4: 3 | AI4: 2 | AJ4: 2 | AK4: 4 | AL4: 3 | AM4: 6
A5: Steals | B5: =C5+SUM(G5:AZ5) -> 147 | C5: 114 | D5: 67 | E5: =D5+SUM(G5:AZ5) -> 100 | F5: =SUM(G5:AZ5) -> 33 | G5: 1 | H5: 1 | I5: 1 | J5: 1 | K5: 1 | L5: 1 | M5: 1 | N5: 3 | O5: 2 | P5: 0 | Q5: 2 | R5: 1 | S5: 0 | U5: 1 | V5: 3 | W5: 1 | X5: 1 | Y5: 0 | Z5: 1 | AA5: 1 | AB5: 0 | AC5: 1 | AD5: 0 | AE5: 2 | AF5: 2 | AG5: 0 | AH5: 0 | AI5: 3 | AJ5: 0 | AK5: 0 | AL5: 1 | AM5: 1
A6: Blocks | B6: =C6+SUM(G6:AZ6) -> 32 | C6: 28 | D6: 9 | E6: =D6+SUM(G6:AZ6) -> 13 | F6: =SUM(G6:AZ6) -> 4 | G6: 0 | H6: 0 | I6: 0 | J6: 0 | K6: 1 | L6: 1 | M6: 0 | N6: 0 | O6: 0 | P6: 0 | Q6: 0 | R6: 0 | S6: 0 | U6: 0 | V6: 0 | W6: 0 | X6: 0 | Y6: 0 | Z6: 0 | AA6: 0 | AB6: 0 | AC6: 0 | AD6: 1 | AE6: 1 | AF6: 0 | AG6: 0 | AH6: 0 | AI6: 0 | AJ6: 0 | AK6: 0 | AL6: 0 | AM6: 0
A7: FGM | B7: =C7+SUM(G7:AZ7) -> 687 | C7: 520 | D7: 280 | E7: =D7+SUM(G7:AZ7) -> 447 | F7: =SUM(G7:AZ7) -> 167 | G7: 5 | H7: 11 | I7: 6 | J7: 4 | K7: 6 | L7: 4 | M7: 4 | N7: 5 | O7: 13 | P7: 7 | Q7: 4 | R7: 7 | S7: 3 | U7: 7 | V7: 6 | W7: 6 | X7: 1 | Y7: 6 | Z7: 4 | AA7: 9 | AB7: 2 | AC7: 5 | AD7: 3 | AE7: 7 | AF7: 1 | AG7: 5 | AH7: 3 | AI7: 4 | AJ7: 7 | AK7: 4 | AL7: 4 | AM7: 4
A8: 3PM | B8: =C8+SUM(G8:AZ8) -> 371 | C8: 248 | D8: 141 | E8: =D8+SUM(G8:AZ8) -> 264 | F8: =SUM(G8:AZ8) -> 123 | G8: 4 | H8: 10 | I8: 2 | J8: 3 | K8: 6 | L8: 3 | M8: 4 | N8: 4 | O8: 8 | P8: 6 | Q8: 3 | R8: 5 | S8: 2 | U8: 3 | V8: 4 | W8: 3 | X8: 0 | Y8: 6 | Z8: 3 | AA8: 7 | AB8: 1 | AC8: 4 | AD8: 2 | AE8: 5 | AF8: 1 | AG8: 4 | AH8: 2 | AI8: 4 | AJ8: 4 | AK8: 3 | AL8: 3 | AM8: 4
A9: Double Doubles | B9: =C9+SUM(G9:AZ9) -> 1 | C9: 0 | D9: 0 | E9: =D9+SUM(G9:AZ9) -> 1 | F9: =SUM(G9:AZ9) -> 1 | G9: 0 | H9: 0 | I9: 0 | J9: 0 | K9: 0 | L9: 0 | M9: 0 | N9: 0 | O9: 0 | P9: 0 | Q9: 0 | R9: 0 | S9: 0 | U9: 0 | V9: 1 | W9: 0 | X9: 0 | Y9: 0 | Z9: 0 | AA9: 0 | AB9: 0 | AC9: 0 | AD9: 0 | AE9: 0 | AF9: 0 | AG9: 0 | AH9: 0 | AI9: 0 | AJ9: 0 | AK9: 0 | AL9: 0 | AM9: 0
A10: MIN | B10: =C10+SUM(G10:AZ10) -> 4394.55 | C10: 3395 | D10: 1658 | E10: =D10+SUM(G10:AZ10) -> 2657.55 | F10: =SUM(G10:AZ10) -> 999.55 | G10: 23.24 | H10: 33.43 | I10: 29.14 | J10: 16.44 | K10: 35.39 | L10: 26.11 | M10: 26.33 | N10: 25.59 | O10: 33.55 | P10: 36.27 | Q10: 36.52 | R10: 36.33 | S10: 39.31 | U10: 36.45 | V10: 30.14 | W10: 34.34 | X10: 20.46 | Y10: 35.4 | Z10: 40.01 | AA10: 37.04 | AB10: 26.28 | AC10: 21.54 | AD10: 31.34 | AE10: 38 | AF10: 32.55 | AG10: 31.57 | AH10: 26.44 | AI10: 29.53 | AJ10: 33.48 | AK10: 30.56 | AL10: 34.31 | AM10: 32.46
A11: FTM | B11: =C11+SUM(G11:AZ11) -> 190 | C11: 150 | D11: 81 | E11: =D11+SUM(G11:AZ11) -> 121 | F11: =SUM(G11:AZ11) -> 40 | G11: 0 | H11: 1 | I11: 0 | J11: 1 | K11: 1 | L11: 0 | M11: 1 | N11: 4 | O11: 1 | P11: 1 | Q11: 4 | R11: 1 | S11: 3 | U11: 4 | V11: 0 | W11: 0 | X11: 0 | Y11: 3 | Z11: 2 | AA11: 1 | AB11: 0 | AC11: 1 | AD11: 2 | AE11: 2 | AF11: 3 | AG11: 0 | AH11: 2 | AI11: 0 | AJ11: 0 | AK11: 2 | AL11: 0 | AM11: 0
A12: GP | B12: =C12+SUM(G12:AZ12) -> 164 | C12: 132 | D12: 48 | E12: =D12+SUM(G12:AZ12) -> 80 | F12: =SUM(G12:AZ12) -> 32 | G12: 1 | H12: 1 | I12: 1 | J12: 1 | K12: 1 | L12: 1 | M12: 1 | N12: 1 | O12: 1 | P12: 1 | Q12: 1 | R12: 1 | S12: 1 | U12: 1 | V12: 1 | W12: 1 | X12: 1 | Y12: 1 | Z12: 1 | AA12: 1 | AB12: 1 | AC12: 1 | AD12: 1 | AE12: 1 | AF12: 1 | AG12: 1 | AH12: 1 | AI12: 1 | AJ12: 1 | AK12: 1 | AL12: 1 | AM12: 1
A15: PLAYOFFS: | B15: All-Time | C15: 2025-26 | D15: 46113
A16: Points | B16: =SUM(D16:BA16) -> 12 | C16: 12 | D16: 12
A17: Rebounds | B17: =SUM(D17:BA17) -> 3 | C17: 3 | D17: 3
A18: Assists | B18: =SUM(D18:BA18) -> 0 | C18: 0 | D18: 0
A19: Steals | B19: =SUM(D19:BA19) -> 1 | C19: 1 | D19: 1
A20: Blocks | B20: =SUM(D20:BA20) -> 0 | C20: 0 | D20: 0
A21: FGM | B21: =SUM(D21:BA21) -> 4 | C21: 4 | D21: 4
A22: 3PM | B22: =SUM(D22:BA22) -> 2 | C22: 2 | D22: 2
A23: Double Doubles | B23: =SUM(D23:BA23) -> 0 | C23: 0 | D23: 0
A24: MIN | B24: =SUM(D24:BA24) -> 32.23 | C24: 32.23 | D24: 32.23
A25: FTM | B25: =SUM(D25:BA25) -> 2 | C25: 2 | D25: 2
A26: GP | B26: =SUM(D26:BA26) -> 1 | C26: 1 | D26: 1

Sheet Javon Freeman-Liberty
A1: JAVON FREEMAN-LIBERTY | B1: All-Time | C1: Pre 2025-26 | D1: 2025-26 | E1: LIN | F1: 46098 | G1: 46100 | H1: 46103 | I1: 46105 | J1: 46106 | K1: 46109
A2: Points | B2: =C2+SUM(F2:AI2) -> 1614 | C2: 1524 | D2: =+SUM(F2:AI2) -> 90 | E2: =SUM(F2:AI2) -> 90 | F2: 17 | G2: 17 | H2: 15 | I2: 8 | J2: 8 | K2: 25
A3: Rebounds | B3: =C3+SUM(F3:AI3) -> 502 | C3: 479 | D3: =+SUM(F3:AI3) -> 23 | E3: =SUM(F3:AI3) -> 23 | F3: 3 | G3: 3 | H3: 4 | I3: 5 | J3: 2 | K3: 6
A4: Assists | B4: =C4+SUM(F4:AI4) -> 275 | C4: 257 | D4: =+SUM(F4:AI4) -> 18 | E4: =SUM(F4:AI4) -> 18 | F4: 0 | G4: 3 | H4: 5 | I4: 3 | J4: 6 | K4: 1
A5: Steals | B5: =C5+SUM(F5:AI5) -> 92 | C5: 86 | D5: =+SUM(F5:AI5) -> 6 | E5: =SUM(F5:AI5) -> 6 | F5: 0 | G5: 3 | H5: 1 | I5: 2 | J5: 0 | K5: 0
A6: Blocks | B6: =C6+SUM(F6:AI6) -> 29 | C6: 28 | D6: =+SUM(F6:AI6) -> 1 | E6: =SUM(F6:AI6) -> 1 | F6: 1 | G6: 0 | H6: 0 | I6: 0 | J6: 0 | K6: 0
A7: FGM | B7: =C7+SUM(F7:AI7) -> 576 | C7: 544 | D7: =+SUM(F7:AI7) -> 32 | E7: =SUM(F7:AI7) -> 32 | F7: 7 | G7: 6 | H7: 4 | I7: 3 | J7: 2 | K7: 10
A8: 3PM | B8: =C8+SUM(F8:AI8) -> 467 | C8: 456 | D8: =+SUM(F8:AI8) -> 11 | E8: =SUM(F8:AI8) -> 11 | F8: 3 | G8: 3 | H8: 1 | I8: 0 | J8: 1 | K8: 3
A9: Double Doubles | B9: =C9+SUM(F9:AI9) -> 14 | C9: 14 | D9: =+SUM(F9:AI9) -> 0 | E9: =SUM(F9:AI9) -> 0 | F9: 0 | G9: 0 | H9: 0 | I9: 0 | J9: 0 | K9: 0
A10: MIN | B10: =C10+SUM(F10:AI10) -> 2640.24 | C10: 2448 | D10: =+SUM(F10:AI10) -> 192.24 | E10: =SUM(F10:AI10) -> 192.24 | F10: 30.43 | G10: 35.48 | H10: 34.39 | I10: 36.34 | J10: 27.55 | K10: 28.05
A11: FTM | B11: =C11+SUM(F11:AI11) -> 188 | C11: 179 | D11: =+SUM(F11:AI11) -> 9 | E11: =SUM(F11:AI11) -> 9 | F11: 0 | G11: 1 | H11: 4 | I11: 2 | J11: 1 | K11: 1
A12: GP | B12: =C12+SUM(F12:AI12) -> 86 | C12: 80 | D12: =+SUM(F12:AI12) -> 6 | E12: =SUM(F12:AI12) -> 6 | F12: 1 | G12: 1 | H12: 1 | I12: 1 | J12: 1 | K12: 1
A15: PLAYOFFS: | B15: All-Time | C15: 2025-26 | D15: 46113
A16: Points | B16: =SUM(D16:BA16) -> 2 | C16: 2 | D16: 2
A17: Rebounds | B17: =SUM(D17:BA17) -> 4 | C17: 4 | D17: 4
A18: Assists | B18: =SUM(D18:BA18) -> 3 | C18: 3 | D18: 3
A19: Steals | B19: =SUM(D19:BA19) -> 1 | C19: 1 | D19: 1
A20: Blocks | B20: =SUM(D20:BA20) -> 0 | C20: 0 | D20: 0
A21: FGM | B21: =SUM(D21:BA21) -> 1 | C21: 1 | D21: 1
A22: 3PM | B22: =SUM(D22:BA22) -> 0 | C22: 0 | D22: 0
A23: Double Doubles | B23: =SUM(D23:BA23) -> 0 | C23: 0 | D23: 0
A24: MIN | B24: =SUM(D24:BA24) -> 17.45 | C24: 17.45 | D24: 17.45
A25: FTM | B25: =SUM(D25:BA25) -> 0 | C25: 0 | D25: 0
A26: GP | B26: =SUM(D26:BA26) -> 1 | C26: 1 | D26: 1

Sheet Ray Harrison
A1: RAY HARRISON | B1: All-Time | C1: CLC | D1: 2025-26 | E1: LIN | F1: 46096 | G1: 46098 | H1: 46100 | I1: 46103 | J1: 46105 | K1: 46106 | L1: 46109
A2: Points | B2: =C2+SUM(F2:AI2) -> 18 | C2: 8 | D2: =C2+SUM(F2:AI2) -> 18 | E2: =SUM(F2:AI2) -> 10 | F2: 0 | H2: 0 | J2: 0 | K2: 10 | L2: 0
A3: Rebounds | B3: =C3+SUM(F3:AI3) -> 11 | C3: 2 | D3: =C3+SUM(F3:AI3) -> 11 | E3: =SUM(F3:AI3) -> 9 | F3: 0 | H3: 0 | J3: 4 | K3: 4 | L3: 1
A4: Assists | B4: =C4+SUM(F4:AI4) -> 4 | C4: 2 | D4: =C4+SUM(F4:AI4) -> 4 | E4: =SUM(F4:AI4) -> 2 | F4: 0 | H4: 1 | J4: 0 | K4: 1 | L4: 0
A5: Steals | B5: =C5+SUM(F5:AI5) -> 7 | C5: 4 | D5: =C5+SUM(F5:AI5) -> 7 | E5: =SUM(F5:AI5) -> 3 | F5: 0 | H5: 0 | J5: 0 | K5: 2 | L5: 1
A6: Blocks | B6: =C6+SUM(F6:AI6) -> 0 | C6: 0 | D6: =C6+SUM(F6:AI6) -> 0 | E6: =SUM(F6:AI6) -> 0 | F6: 0 | H6: 0 | J6: 0 | K6: 0 | L6: 0
A7: FGM | B7: =C7+SUM(F7:AI7) -> 7 | C7: 3 | D7: =C7+SUM(F7:AI7) -> 7 | E7: =SUM(F7:AI7) -> 4 | F7: 0 | H7: 0 | J7: 0 | K7: 4 | L7: 0
A8: 3PM | B8: =C8+SUM(F8:AI8) -> 4 | C8: 2 | D8: =C8+SUM(F8:AI8) -> 4 | E8: =SUM(F8:AI8) -> 2 | F8: 0 | H8: 0 | J8: 0 | K8: 2 | L8: 0
A9: Double Doubles | B9: =C9+SUM(F9:AI9) -> 0 | C9: 0 | D9: =C9+SUM(F9:AI9) -> 0 | E9: =SUM(F9:AI9) -> 0 | F9: 0 | H9: 0 | J9: 0 | K9: 0 | L9: 0
A10: MIN | B10: =C10+SUM(F10:AI10) -> 111.61 | C10: 37 | D10: =C10+SUM(F10:AI10) -> 111.61 | E10: =SUM(F10:AI10) -> 74.61 | F10: 11.44 | H10: 9.14 | J10: 16.13 | K10: 26.55 | L10: 11.35
A11: FTM | B11: =C11+SUM(F11:AI11) -> 0 | C11: 0 | D11: =C11+SUM(F11:AI11) -> 0 | E11: =SUM(F11:AI11) -> 0 | F11: 0 | H11: 0 | J11: 0 | K11: 0 | L11: 0
A12: GP | B12: =C12+SUM(F12:AI12) -> 10 | C12: 5 | D12: =C12+SUM(F12:AI12) -> 10 | E12: =SUM(F12:AI12) -> 5 | F12: 1 | H12: 1 | J12: 1 | K12: 1 | L12: 1
A15: PLAYOFFS: | B15: All-Time | C15: 2025-26 | D15: 46113
A16: Points | B16: =SUM(D16:BA16) -> 0 | C16: 0
A17: Rebounds | B17: =SUM(D17:BA17) -> 0 | C17: 0
A18: Assists | B18: =SUM(D18:BA18) -> 0 | C18: 0
A19: Steals | B19: =SUM(D19:BA19) -> 0 | C19: 0
A20: Blocks | B20: =SUM(D20:BA20) -> 0 | C20: 0
A21: FGM | B21: =SUM(D21:BA21) -> 0 | C21: 0
A22: 3PM | B22: =SUM(D22:BA22) -> 0 | C22: 0
A23: Double Doubles | B23: =SUM(D23:BA23) -> 0 | C23: 0
A24: MIN | B24: =SUM(D24:BA24) -> 0 | C24: 0
A25: FTM | B25: =SUM(D25:BA25) -> 0 | C25: 0
A26: GP | B26: =SUM(D26:BA26) -> 0 | C26: 0

Sheet Chaney Johnson
A1: CHANEY JOHNSON | B1: All-Time | C1: CLE | D1: 2025-26 | E1: LIN | F1: 45659 | G1: 45661 | H1: 45663 | I1: 45665 | J1: 45666 | K1: 45669 | L1: 46040 | M1: 46041 | N1: 46043 | O1: 46045 | P1: 46048 | Q1: 46050 | R1: 46055 | S1: 46058 | T1: 46059 | U1: 46061 | V1: 46063 | W1: 46065 | X1: 46072 | Y1: 46073 | Z1: 46078 | AA1: 46079 | AB1: 46082 | AC1: 46085 | AD1: 46087
A2: Points | B2: =C2+SUM(F2:AK2) -> 558 | C2: 205 | D2: =C2+SUM(F2:AK2) -> 558 | E2: =SUM(F2:AK2) -> 353 | F2: 11 | G2: 22 | H2: 12 | I2: 15 | J2: 12 | L2: 21 | M2: 8 | N2: 14 | O2: 16 | P2: 10 | Q2: 12 | R2: 8 | S2: 11 | T2: 12 | U2: 13 | V2: 20 | W2: 15 | X2: 11 | Y2: 10 | Z2: 19 | AA2: 29 | AB2: 15 | AC2: 17 | AD2: 20
A3: Rebounds | B3: =C3+SUM(F3:AK3) -> 237 | C3: 87 | D3: =C3+SUM(F3:AK3) -> 237 | E3: =SUM(F3:AK3) -> 150 | F3: 11 | G3: 7 | H3: 5 | I3: 8 | J3: 5 | L3: 4 | M3: 3 | N3: 15 | O3: 4 | P3: 5 | Q3: 9 | R3: 2 | S3: 3 | T3: 5 | U3: 3 | V3: 6 | W3: 4 | X3: 4 | Y3: 10 | Z3: 8 | AA3: 7 | AB3: 10 | AC3: 7 | AD3: 5
A4: Assists | B4: =C4+SUM(F4:AK4) -> 78 | C4: 30 | D4: =C4+SUM(F4:AK4) -> 78 | E4: =SUM(F4:AK4) -> 48 | F4: 4 | G4: 2 | H4: 3 | I4: 0 | J4: 1 | L4: 1 | M4: 2 | N4: 3 | O4: 3 | P4: 2 | Q4: 0 | R4: 0 | S4: 4 | T4: 2 | U4: 1 | V4: 1 | W4: 1 | X4: 3 | Y4: 1 | Z4: 1 | AA4: 1 | AB4: 3 | AC4: 4 | AD4: 5
A5: Steals | B5: =C5+SUM(F5:AK5) -> 60 | C5: 23 | D5: =C5+SUM(F5:AK5) -> 60 | E5: =SUM(F5:AK5) -> 37 | F5: 2 | G5: 3 | H5: 3 | I5: 3 | J5: 0 | L5: 0 | M5: 2 | N5: 0 | O5: 0 | P5: 4 | Q5: 2 | R5: 2 | S5: 1 | T5: 1 | U5: 3 | V5: 2 | W5: 1 | X5: 1 | Y5: 1 | Z5: 3 | AA5: 0 | AB5: 0 | AC5: 2 | AD5: 1
A6: Blocks | B6: =C6+SUM(F6:AK6) -> 41 | C6: 18 | D6: =C6+SUM(F6:AK6) -> 41 | E6: =SUM(F6:AK6) -> 23 | F6: 3 | G6: 0 | H6: 0 | I6: 1 | J6: 1 | L6: 1 | M6: 1 | N6: 1 | O6: 0 | P6: 1 | Q6: 1 | R6: 0 | S6: 2 | T6: 1 | U6: 1 | V6: 2 | W6: 2 | X6: 0 | Y6: 0 | Z6: 2 | AA6: 2 | AB6: 0 | AC6: 0 | AD6: 1
A7: FGM | B7: =C7+SUM(F7:AK7) -> 206 | C7: 81 | D7: =C7+SUM(F7:AK7) -> 206 | E7: =SUM(F7:AK7) -> 125 | F7: 3 | G7: 8 | H7: 4 | I7: 4 | J7: 5 | L7: 9 | M7: 2 | N7: 6 | O7: 5 | P7: 3 | Q7: 4 | R7: 3 | S7: 4 | T7: 2 | U7: 5 | V7: 7 | W7: 5 | X7: 5 | Y7: 5 | Z7: 8 | AA7: 10 | AB7: 4 | AC7: 8 | AD7: 6
A8: 3PM | B8: =C8+SUM(F8:AK8) -> 34 | C8: 12 | D8: =C8+SUM(F8:AK8) -> 34 | E8: =SUM(F8:AK8) -> 22 | F8: 0 | G8: 3 | H8: 0 | I8: 1 | J8: 0 | L8: 1 | M8: 0 | N8: 1 | O8: 2 | P8: 1 | Q8: 1 | R8: 2 | S8: 1 | T8: 0 | U8: 0 | V8: 1 | W8: 1 | X8: 1 | Y8: 0 | Z8: 1 | AA8: 3 | AB8: 1 | AC8: 1 | AD8: 0
A9: Double Doubles | B9: =C9+SUM(F9:AK9) -> 6 | C9: 2 | D9: =C9+SUM(F9:AK9) -> 6 | E9: =SUM(F9:AK9) -> 4 | F9: 1 | G9: 0 | H9: 0 | I9: 0 | J9: 0 | L9: 0 | M9: 0 | N9: 1 | O9: 0 | P9: 0 | Q9: 0 | R9: 0 | S9: 0 | T9: 0 | U9: 0 | V9: 0 | W9: 0 | X9: 0 | Y9: 1 | Z9: 0 | AA9: 0 | AB9: 1 | AC9: 0 | AD9: 0
A10: MIN | B10: =C10+SUM(F10:AK10) -> 1048.31 | C10: 408 | D10: =C10+SUM(F10:AK10) -> 1048.31 | E10: =SUM(F10:AK10) -> 640.31 | F10: 34.27 | G10: 27.52 | H10: 31.42 | I10: 39.39 | J10: 23.45 | L10: 23.25 | M10: 23.56 | N10: 27.13 | O10: 20.06 | P10: 30.32 | Q10: 24.51 | R10: 19.44 | S10: 21.36 | T10: 24.37 | U10: 16.36 | V10: 30.51 | W10: 25.06 | X10: 23.55 | Y10: 29.36 | Z10: 30.27 | AA10: 28.3 | AB10: 29.14 | AC10: 27.16 | AD10: 30.55
A11: FTM | B11: =C11+SUM(F11:AK11) -> 67 | C11: 19 | D11: =C11+SUM(F11:AK11) -> 67 | E11: =SUM(F11:AK11) -> 48 | F11: 3 | G11: 3 | H11: 2 | I11: 3 | J11: 1 | L11: 2 | M11: 2 | N11: 1 | O11: 2 | P11: 2 | Q11: 2 | R11: 0 | S11: 1 | T11: 5 | U11: 2 | V11: 3 | W11: 2 | X11: 0 | Y11: 0 | Z11: 1 | AA11: 3 | AB11: 3 | AC11: 0 | AD11: 5
A12: GP | B12: =C12+SUM(F12:AK12) -> 40 | C12: 16 | D12: =C12+SUM(F12:AK12) -> 40 | E12: =SUM(F12:AK12) -> 24 | F12: 1 | G12: 1 | H12: 1 | I12: 1 | J12: 1 | L12: 1 | M12: 1 | N12: 1 | O12: 1 | P12: 1 | Q12: 1 | R12: 1 | S12: 1 | T12: 1 | U12: 1 | V12: 1 | W12: 1 | X12: 1 | Y12: 1 | Z12: 1 | AA12: 1 | AB12: 1 | AC12: 1 | AD12: 1
A15: PLAYOFFS: | B15: All-Time | C15: 2025-26 | D15: 46113
A16: Points | B16: =SUM(D16:BA16) -> 22 | C16: 22 | D16: 22
A17: Rebounds | B17: =SUM(D17:BA17) -> 6 | C17: 6 | D17: 6
A18: Assists | B18: =SUM(D18:BA18) -> 1 | C18: 1 | D18: 1
A19: Steals | B19: =SUM(D19:BA19) -> 1 | C19: 1 | D19: 1
A20: Blocks | B20: =SUM(D20:BA20) -> 1 | C20: 1 | D20: 1
A21: FGM | B21: =SUM(D21:BA21) -> 8 | C21: 8 | D21: 8
A22: 3PM | B22: =SUM(D22:BA22) -> 0 | C22: 0 | D22: 0
A23: Double Doubles | B23: =SUM(D23:BA23) -> 0 | C23: 0 | D23: 0
A24: MIN | B24: =SUM(D24:BA24) -> 32.3 | C24: 32.3 | D24: 32.3
A25: FTM | B25: =SUM(D25:BA25) -> 3 | C25: 3 | D25: 3
A26: GP | B26: =SUM(D26:BA26) -> 1 | C26: 1 | D26: 1

Sheet E.J. Liddell
A1: E.J. LIDDELL | B1: All-Time | C1: Pre 2025 | D1: LIN | E1: 45996 | F1: 45997 | G1: 46000 | H1: 46001 | I1: 46003 | J1: 46011 | K1: 46013 | L1: 46019 | M1: 45659 | N1: 45661 | O1: 45663 | P1: 45665 | Q1: 45666 | R1: 45669 | S1: 45671 | T1: 46040 | U1: 46041 | V1: 46043 | W1: 46045 | X1: 46048 | Y1: 46050 | Z1: 46055 | AA1: 46058 | AB1: 46059 | AC1: 46061 | AD1: 46063 | AE1: 46065 | AF1: 46072 | AG1: 46073 | AH1: 46078 | AI1: 46079 | AJ1: 46082 | AK1: 46085 | AL1: 46087
A2: Points | B2: =C2+SUM(E2:AS2) -> 1508 | C2: 1052 | D2: =SUM(E2:AS2) -> 456 | E2: 17 | F2: 21 | G2: 13 | J2: 17 | K2: 25 | L2: 24 | N2: 26 | O2: 10 | S2: 17 | T2: 12 | U2: 18 | V2: 25 | W2: 8 | Z2: 14 | AA2: 30 | AB2: 32 | AC2: 19 | AD2: 9 | AE2: 13 | AF2: 8 | AG2: 14 | AH2: 13 | AI2: 4 | AJ2: 14 | AK2: 17 | AL2: 36
A3: Rebounds | B3: =C3+SUM(E3:AS3) -> 682 | C3: 459 | D3: =SUM(E3:AS3) -> 223 | E3: 11 | F3: 13 | G3: 10 | J3: 9 | K3: 14 | L3: 9 | N3: 8 | O3: 2 | S3: 9 | T3: 5 | U3: 7 | V3: 9 | W3: 11 | Z3: 3 | AA3: 6 | AB3: 10 | AC3: 3 | AD3: 5 | AE3: 12 | AF3: 10 | AG3: 8 | AH3: 9 | AI3: 9 | AJ3: 9 | AK3: 9 | AL3: 13
A4: Assists | B4: =C4+SUM(E4:AS4) -> 175 | C4: 130 | D4: =SUM(E4:AS4) -> 45 | E4: 2 | F4: 2 | G4: 1 | J4: 3 | K4: 1 | L4: 2 | N4: 3 | O4: 1 | S4: 2 | T4: 2 | U4: 1 | V4: 1 | W4: 1 | Z4: 1 | AA4: 3 | AB4: 2 | AC4: 0 | AD4: 1 | AE4: 2 | AF4: 3 | AG4: 1 | AH4: 4 | AI4: 4 | AJ4: 0 | AK4: 1 | AL4: 1
A5: Steals | B5: =C5+SUM(E5:AS5) -> 64 | C5: 43 | D5: =SUM(E5:AS5) -> 21 | E5: 1 | F5: 1 | G5: 0 | J5: 3 | K5: 3 | L5: 1 | N5: 0 | O5: 0 | S5: 3 | T5: 1 | U5: 2 | V5: 1 | W5: 0 | Z5: 1 | AA5: 0 | AB5: 0 | AC5: 0 | AD5: 1 | AE5: 1 | AF5: 0 | AG5: 1 | AH5: 1 | AI5: 0 | AJ5: 0 | AK5: 0 | AL5: 0
A6: Blocks | B6: =C6+SUM(E6:AS6) -> 176 | C6: 136 | D6: =SUM(E6:AS6) -> 40 | E6: 3 | F6: 6 | G6: 2 | J6: 2 | K6: 0 | L6: 4 | N6: 1 | O6: 0 | S6: 2 | T6: 0 | U6: 4 | V6: 1 | W6: 0 | Z6: 1 | AA6: 2 | AB6: 2 | AC6: 0 | AD6: 1 | AE6: 0 | AF6: 2 | AG6: 2 | AH6: 0 | AI6: 3 | AJ6: 1 | AK6: 0 | AL6: 1
A7: FGM | B7: =C7+SUM(E7:AS7) -> 522 | C7: 378 | D7: =SUM(E7:AS7) -> 144 | E7: 5 | F7: 10 | G7: 3 | J7: 6 | K7: 9 | L7: 7 | N7: 7 | O7: 4 | S7: 4 | T7: 5 | U7: 7 | V7: 8 | W7: 1 | Z7: 4 | AA7: 8 | AB7: 10 | AC7: 4 | AD7: 4 | AE7: 4 | AF7: 3 | AG7: 5 | AH7: 3 | AI7: 2 | AJ7: 3 | AK7: 7 | AL7: 11
A8: 3PM | B8: =C8+SUM(E8:AS8) -> 144 | C8: 103 | D8: =SUM(E8:AS8) -> 41 | E8: 2 | F8: 0 | G8: 3 | J8: 1 | K8: 1 | L8: 2 | N8: 2 | O8: 2 | S8: 1 | T8: 2 | U8: 2 | V8: 4 | W8: 0 | Z8: 1 | AA8: 3 | AB8: 4 | AC8: 3 | AD8: 0 | AE8: 1 | AF8: 0 | AG8: 2 | AH8: 1 | AI8: 0 | AJ8: 0 | AK8: 1 | AL8: 3
A9: Double Doubles | B9: =C9+SUM(E9:AS9) -> 21 | C9: 14 | D9: =SUM(E9:AS9) -> 7 | E9: 1 | F9: 1 | G9: 1 | J9: 0 | K9: 1 | L9: 0 | N9: 0 | O9: 0 | S9: 0 | T9: 0 | U9: 0 | V9: 0 | W9: 0 | Z9: 0 | AA9: 0 | AB9: 1 | AC9: 0 | AD9: 0 | AE9: 1 | AF9: 0 | AG9: 0 | AH9: 0 | AI9: 0 | AJ9: 0 | AK9: 0 | AL9: 1
A10: MIN | B10: =C10+SUM(E10:AS10) -> 2660.41 | C10: 1904 | D10: =SUM(E10:AS10) -> 756.41 | E10: 24.28 | F10: 39.51 | G10: 34.11 | J10: 33.27 | K10: 39.55 | L10: 31.02 | N10: 35.47 | O10: 7.48 | S10: 24.33 | T10: 24.36 | U10: 25.46 | V10: 23.58 | W10: 27.4 | Z10: 28.16 | AA10: 29.3 | AB10: 36.05 | AC10: 28.4 | AD10: 19.45 | AE10: 26.55 | AF10: 32.47 | AG10: 29.32 | AH10: 35.3 | AI10: 30.47 | AJ10: 30.57 | AK10: 32.46 | AL10: 28.09
A11: FTM | B11: =C11+SUM(E11:AS11) -> 194 | C11: 114 | D11: 80 | E11: 3 | F11: 1 | G11: 2 | J11: 3 | K11: 3 | L11: 5 | N11: 7 | O11: 0 | S11: 5 | T11: 0 | U11: 1 | V11: 3 | W11: 4 | Z11: 4 | AA11: 6 | AB11: 5 | AC11: 4 | AD11: 1 | AE11: 2 | AF11: 1 | AG11: 2 | AH11: 3 | AI11: 0 | AJ11: 5 | AK11: 2 | AL11: 8
A12: GP | B12: =C12+SUM(E12:AS12) -> 91 | C12: 65 | D12: =SUM(E12:AS12) -> 26 | E12: 1 | F12: 1 | G12: 1 | J12: 1 | K12: 1 | L12: 1 | N12: 1 | O12: 1 | S12: 1 | T12: 1 | U12: 1 | V12: 1 | W12: 1 | Z12: 1 | AA12: 1 | AB12: 1 | AC12: 1 | AD12: 1 | AE12: 1 | AF12: 1 | AG12: 1 | AH12: 1 | AI12: 1 | AJ12: 1 | AK12: 1 | AL12: 1
A15: PLAYOFFS: | B15: All-Time | C15: 2025-26 | D15: 46113
A16: Points | B16: =SUM(D16:BA16) -> 32 | C16: 32 | D16: 32
A17: Rebounds | B17: =SUM(D17:BA17) -> 9 | C17: 9 | D17: 9
A18: Assists | B18: =SUM(D18:BA18) -> 4 | C18: 4 | D18: 4
A19: Steals | B19: =SUM(D19:BA19) -> 0 | C19: 0 | D19: 0
A20: Blocks | B20: =SUM(D20:BA20) -> 3 | C20: 3 | D20: 3
A21: FGM | B21: =SUM(D21:BA21) -> 10 | C21: 10 | D21: 10
A22: 3PM | B22: =SUM(D22:BA22) -> 2 | C22: 2 | D22: 2
A23: Double Doubles | B23: =SUM(D23:BA23) -> 0 | C23: 0 | D23: 0
A24: MIN | B24: =SUM(D24:BA24) -> 38.12 | C24: 38.12 | D24: 38.12
A25: FTM | B25: =SUM(D25:BA25) -> 6 | C25: 6 | D25: 6
A26: GP | B26: =SUM(D26:BA26) -> 1 | C26: 1 | D26: 1

Sheet Jamal Mashburn Jr.
A1: JAMAL MASHBURN JR. | B1: All-Time | C1: WCK | D1: 2025-26 | E1: LIN | F1: 46030 | G1: 46031 | H1: 46034 | I1: 46036 | J1: 46040 | K1: 46041 | L1: 46043 | M1: 46045 | N1: 46048 | O1: 46050 | P1: 46055 | Q1: 46058 | R1: 46059 | S1: 46061 | T1: 46063 | U1: 46065 | V1: 46072 | W1: 46073 | X1: 46078 | Y1: 46079 | Z1: 46082 | AA1: 46085 | AB1: 46087 | AC1: 46096 | AD1: 46098 | AE1: 46100 | AF1: 46103 | AG1: 46105 | AH1: 46106 | AI1: 46109
A2: Points | B2: =C2+SUM(F2:AI2) -> 125 | C2: 58 | D2: =C2+SUM(F2:AI2) -> 125 | E2: =SUM(F2:AI2) -> 67 | F2: 0 | L2: 0 | Q2: 3 | S2: 0 | AC2: 7 | AD2: 4 | AE2: 10 | AF2: 6 | AG2: 9 | AH2: 24 | AI2: 4
A3: Rebounds | B3: =C3+SUM(F3:AI3) -> 26 | C3: 13 | D3: =C3+SUM(F3:AI3) -> 26 | E3: =SUM(F3:AI3) -> 13 | F3: 0 | L3: 0 | Q3: 0 | S3: 0 | AC3: 1 | AD3: 0 | AE3: 1 | AF3: 2 | AG3: 2 | AH3: 6 | AI3: 1
A4: Assists | B4: =C4+SUM(F4:AI4) -> 16 | C4: 9 | D4: =C4+SUM(F4:AI4) -> 16 | E4: =SUM(F4:AI4) -> 7 | F4: 0 | L4: 0 | Q4: 0 | S4: 0 | AC4: 1 | AD4: 0 | AE4: 1 | AF4: 0 | AG4: 0 | AH4: 5 | AI4: 0
A5: Steals | B5: =C5+SUM(F5:AI5) -> 2 | C5: 2 | D5: =C5+SUM(F5:AI5) -> 2 | E5: =SUM(F5:AI5) -> 0 | F5: 0 | L5: 0 | Q5: 0 | S5: 0 | AC5: 0 | AD5: 0 | AE5: 0 | AF5: 0 | AG5: 0 | AH5: 0 | AI5: 0
A6: Blocks | B6: =C6+SUM(F6:AI6) -> 0 | C6: 0 | D6: =C6+SUM(F6:AI6) -> 0 | E6: =SUM(F6:AI6) -> 0 | F6: 0 | L6: 0 | Q6: 0 | S6: 0 | AC6: 0 | AD6: 0 | AE6: 0 | AF6: 0 | AG6: 0 | AH6: 0 | AI6: 0
A7: FGM | B7: =C7+SUM(F7:AI7) -> 47 | C7: 22 | D7: =C7+SUM(F7:AI7) -> 47 | E7: =SUM(F7:AI7) -> 25 | F7: 0 | L7: 0 | Q7: 1 | S7: 0 | AC7: 2 | AD7: 2 | AE7: 4 | AF7: 1 | AG7: 3 | AH7: 10 | AI7: 2
A8: 3PM | B8: =C8+SUM(F8:AI8) -> 11 | C8: 5 | D8: =C8+SUM(F8:AI8) -> 11 | E8: =SUM(F8:AI8) -> 6 | F8: 0 | L8: 0 | Q8: 1 | S8: 0 | AC8: 1 | AD8: 0 | AE8: 2 | AF8: 0 | AG8: 1 | AH8: 1 | AI8: 0
A9: Double Doubles | B9: =C9+SUM(F9:AI9) -> 0 | C9: 0 | D9: =C9+SUM(F9:AI9) -> 0 | E9: =SUM(F9:AI9) -> 0 | F9: 0 | L9: 0 | Q9: 0 | S9: 0 | AC9: 0 | AD9: 0 | AE9: 0 | AF9: 0 | AG9: 0 | AH9: 0 | AI9: 0
A10: MIN | B10: 0 | C10: 126 | D10: =C10+SUM(F10:AI10) -> 261.75 | E10: =SUM(F10:AI10) -> 135.75 | F10: 1.54 | L10: 3.03 | Q10: 2.3 | S10: 2.44 | AC10: 18.26 | AD10: 12.01 | AE10: 17.03 | AF10: 13.46 | AG10: 19.47 | AH10: 33.15 | AI10: 13.06
A11: FTM | B11: =C11+SUM(F11:AI11) -> 12 | C11: 5 | D11: =C11+SUM(F11:AI11) -> 12 | E11: =SUM(F11:AI11) -> 7 | F11: 0 | L11: 0 | Q11: 1 | S11: 0 | AC11: 1 | AD11: 0 | AE11: 0 | AF11: 2 | AG11: 1 | AH11: 2 | AI11: 0
A12: GP | B12: =C12+SUM(F12:AI12) -> 17 | C12: 6 | D12: =C12+SUM(F12:AI12) -> 17 | E12: =SUM(F12:AI12) -> 11 | F12: 1 | L12: 1 | Q12: 1 | S12: 1 | AC12: 1 | AD12: 1 | AE12: 1 | AF12: 1 | AG12: 1 | AH12: 1 | AI12: 1
A15: PLAYOFFS: | B15: All-Time | C15: 2025-26 | D15: 46113
A16: Points | B16: =SUM(D16:BA16) -> 0 | C16: 0
A17: Rebounds | B17: =SUM(D17:BA17) -> 0 | C17: 0
A18: Assists | B18: =SUM(D18:BA18) -> 0 | C18: 0
A19: Steals | B19: =SUM(D19:BA19) -> 0 | C19: 0
A20: Blocks | B20: =SUM(D20:BA20) -> 0 | C20: 0
A21: FGM | B21: =SUM(D21:BA21) -> 0 | C21: 0
A22: 3PM | B22: =SUM(D22:BA22) -> 0 | C22: 0
A23: Double Doubles | B23: =SUM(D23:BA23) -> 0 | C23: 0
A24: MIN | B24: =SUM(D24:BA24) -> 0 | C24: 0
A25: FTM | B25: =SUM(D25:BA25) -> 0 | C25: 0
A26: GP | B26: =SUM(D26:BA26) -> 0 | C26: 0

Sheet Josh Minott
A1: JOSH MINOTT | B1: All-Time | C1: IOWA (22-24) | D1: 2025-26 | E1: LIN | F1: 46072 | G1: 46073 | H1: 46078
A2: Points | B2: =C2+SUM(F2:AI2) -> 646 | C2: 615 | D2: =+SUM(F2:AI2) -> 31 | E2: =SUM(F2:AI2) -> 31 | F2: 17 | G2: 9 | H2: 5
A3: Rebounds | B3: =C3+SUM(F3:AI3) -> 248 | C3: 239 | D3: =+SUM(F3:AI3) -> 9 | E3: =SUM(F3:AI3) -> 9 | F3: 1 | G3: 4 | H3: 4
A4: Assists | B4: =C4+SUM(F4:AI4) -> 92 | C4: 86 | D4: =+SUM(F4:AI4) -> 6 | E4: =SUM(F4:AI4) -> 6 | F4: 2 | G4: 2 | H4: 2
A5: Steals | B5: =C5+SUM(F5:AI5) -> 39 | C5: 37 | D5: =+SUM(F5:AI5) -> 2 | E5: =SUM(F5:AI5) -> 2 | F5: 2 | G5: 0 | H5: 0
A6: Blocks | B6: =C6+SUM(F6:AI6) -> 60 | C6: 55 | D6: =+SUM(F6:AI6) -> 5 | E6: =SUM(F6:AI6) -> 5 | F6: 2 | G6: 3 | H6: 0
A7: FGM | B7: =C7+SUM(F7:AI7) -> 256 | C7: 246 | D7: =+SUM(F7:AI7) -> 10 | E7: =SUM(F7:AI7) -> 10 | F7: 5 | G7: 3 | H7: 2
A8: 3PM | B8: =C8+SUM(F8:AI8) -> 41 | C8: 33 | D8: =+SUM(F8:AI8) -> 8 | E8: =SUM(F8:AI8) -> 8 | F8: 5 | G8: 2 | H8: 1
A9: Double Doubles | B9: =C9+SUM(F9:AI9) -> 8 | C9: 8 | D9: =+SUM(F9:AI9) -> 0 | E9: =SUM(F9:AI9) -> 0 | F9: 0 | G9: 0 | H9: 0
A10: MIN | B10: =C10+SUM(F10:AI10) -> 1108.51 | C10: 1035 | D10: =+SUM(F10:AI10) -> 73.51 | E10: =SUM(F10:AI10) -> 73.51 | F10: 24.05 | G10: 25.46 | H10: 24
A11: FTM | B11: =C11+SUM(F11:AI11) -> 55 | C11: 53 | D11: =+SUM(F11:AI11) -> 2 | E11: =SUM(F11:AI11) -> 2 | F11: 1 | G11: 1 | H11: 0
A12: GP | B12: =C12+SUM(F12:AI12) -> 35 | C12: 32 | D12: =+SUM(F12:AI12) -> 3 | E12: =SUM(F12:AI12) -> 3 | F12: 1 | G12: 1 | H12: 1

Sheet David Muoka
A1: DAVID MUOKA | B1: All-Time | C1: Pre 2025 | D1: 2023-24 (LIN) | E1: LIN | F1: 2025-26 | G1: 45968 | H1: 45970 | I1: 45975 | J1: 45976 | K1: 45983 | L1: 45985 | M1: 45987 | N1: 45990 | O1: 45992 | P1: 45996 | Q1: 45997 | R1: 46000 | S1: 46001 | T1: 46003 | U1: 46011 | V1: 46013 | W1: 46019 | X1: 45659 | Y1: 45661 | Z1: 45663 | AA1: 45665 | AB1: 45666 | AC1: 45669 | AD1: 45671 | AE1: 46040 | AF1: 46041 | AG1: 46043 | AH1: 46045 | AI1: 46048 | AJ1: 46050 | AK1: 46055 | AL1: 46058 | AM1: 46059 | AN1: 46061 | AO1: 46063 | AP1: 46065 | AQ1: 46072 | AR1: 46073 | AS1: 46078 | AT1: 46079 | AU1: 46082 | AV1: 46085 | AW1: 46087 | AX1: 46096 | AY1: 46098 | AZ1: 46100 | BA1: 46103 | BB1: 46105 | BC1: 46106 | BD1: 46109
A2: Points | B2: =C2+SUM(G2:BD2) -> 935 | C2: 683 | D2: 171 | E2: =D2+SUM(G2:BD2) -> 423 | F2: =SUM(G2:AI2) -> 91 | G2: 0 | H2: 4 | I2: 0 | K2: 0 | L2: 2 | M2: 6 | N2: 6 | O2: 2 | P2: 4 | Q2: 2 | S2: 10 | U2: 6 | V2: 0 | W2: 6 | X2: 4 | Y2: 4 | Z2: 2 | AA2: 2 | AB2: 2 | AC2: 17 | AD2: 4 | AE2: 2 | AG2: 0 | AH2: 0 | AI2: 6 | AJ2: 14 | AK2: 6 | AL2: 4 | AM2: 6 | AN2: 2 | AO2: 4 | AP2: 8 | AQ2: 6 | AR2: 0 | AT2: 6 | AU2: 7 | AV2: 2 | AW2: 2 | AX2: 14 | AY2: 12 | AZ2: 12 | BA2: 20 | BB2: 12 | BC2: 16 | BD2: 8
A3: Rebounds | B3: =C3+SUM(G3:BD3) -> 823 | C3: 598 | D3: 189 | E3: =D3+SUM(G3:BD3) -> 414 | F3: =SUM(G3:AI3) -> 102 | G3: 2 | H3: 4 | I3: 3 | K3: 5 | L3: 2 | M3: 7 | N3: 7 | O3: 4 | P3: 5 | Q3: 1 | S3: 3 | U3: 4 | V3: 2 | W3: 7 | X3: 4 | Y3: 1 | Z3: 5 | AA3: 5 | AB3: 3 | AC3: 8 | AD3: 6 | AE3: 7 | AG3: 0 | AH3: 0 | AI3: 7 | AJ3: 5 | AK3: 8 | AL3: 4 | AM3: 9 | AN3: 4 | AO3: 1 | AP3: 6 | AQ3: 8 | AR3: 2 | AT3: 3 | AU3: 8 | AV3: 5 | AW3: 4 | AX3: 6 | AY3: 11 | AZ3: 7 | BA3: 9 | BB3: 8 | BC3: 8 | BD3: 7
A4: Assists | B4: =C4+SUM(G4:BD4) -> 153 | C4: 110 | D4: 22 | E4: =D4+SUM(G4:BD4) -> 65 | F4: =SUM(G4:AI4) -> 17 | G4: 0 | H4: 0 | I4: 0 | K4: 3 | L4: 0 | M4: 2 | N4: 1 | O4: 1 | P4: 0 | Q4: 0 | S4: 0 | U4: 0 | V4: 0 | W4: 2 | X4: 0 | Y4: 0 | Z4: 2 | AA4: 1 | AB4: 1 | AC4: 2 | AD4: 1 | AE4: 0 | AG4: 0 | AH4: 0 | AI4: 1 | AJ4: 3 | AK4: 1 | AL4: 0 | AM4: 0 | AN4: 0 | AO4: 0 | AP4: 1 | AQ4: 1 | AR4: 1 | AT4: 1 | AU4: 2 | AV4: 0 | AW4: 0 | AX4: 1 | AY4: 3 | AZ4: 3 | BA4: 0 | BB4: 2 | BC4: 3 | BD4: 4
A5: Steals | B5: =C5+SUM(G5:BD5) -> 51 | C5: 35 | D5: 6 | E5: =D5+SUM(G5:BD5) -> 22 | F5: =SUM(G5:AI5) -> 8 | G5: 1 | H5: 0 | I5: 0 | K5: 0 | L5: 0 | M5: 0 | N5: 1 | O5: 0 | P5: 0 | Q5: 1 | S5: 0 | U5: 0 | V5: 1 | W5: 1 | X5: 1 | Y5: 0 | Z5: 1 | AA5: 0 | AB5: 0 | AC5: 0 | AD5: 0 | AE5: 0 | AG5: 0 | AH5: 0 | AI5: 1 | AJ5: 0 | AK5: 0 | AL5: 0 | AM5: 1 | AN5: 0 | AO5: 0 | AP5: 1 | AQ5: 1 | AR5: 0 | AT5: 0 | AU5: 1 | AV5: 0 | AW5: 0 | AX5: 0 | AY5: 0 | AZ5: 1 | BA5: 2 | BB5: 1 | BC5: 0 | BD5: 0
A6: Blocks | B6: =C6+SUM(G6:BD6) -> 194 | C6: 148 | D6: 50 | E6: =D6+SUM(G6:BD6) -> 96 | F6: =SUM(G6:BD6) -> 46 | G6: 1 | H6: 0 | I6: 1 | K6: 0 | L6: 0 | M6: 0 | N6: 0 | O6: 1 | P6: 2 | Q6: 1 | S6: 3 | U6: 1 | V6: 0 | W6: 0 | X6: 0 | Y6: 0 | Z6: 0 | AA6: 2 | AB6: 1 | AC6: 1 | AD6: 0 | AE6: 1 | AG6: 0 | AH6: 1 | AI6: 2 | AJ6: 1 | AK6: 3 | AL6: 0 | AM6: 2 | AN6: 1 | AO6: 0 | AP6: 1 | AQ6: 0 | AR6: 0 | AT6: 0 | AU6: 3 | AV6: 3 | AW6: 1 | AX6: 2 | AY6: 0 | AZ6: 3 | BA6: 3 | BB6: 0 | BC6: 5 | BD6: 0
A7: FGM | B7: =C7+SUM(G7:BD7) -> 425 | C7: 312 | D7: 76 | E7: =D7+SUM(G7:BD7) -> 189 | F7: =SUM(G7:AI7) -> 39 | G7: 0 | H7: 2 | I7: 0 | K7: 0 | L7: 1 | M7: 2 | N7: 3 | O7: 1 | P7: 2 | Q7: 1 | S7: 4 | U7: 3 | V7: 0 | W7: 3 | X7: 2 | Y7: 2 | Z7: 1 | AA7: 0 | AB7: 1 | AC7: 6 | AD7: 2 | AE7: 1 | AG7: 0 | AH7: 0 | AI7: 2 | AJ7: 7 | AK7: 2 | AL7: 2 | AM7: 3 | AN7: 1 | AO7: 2 | AP7: 4 | AQ7: 3 | AR7: 0 | AT7: 3 | AU7: 3 | AV7: 1 | AW7: 1 | AX7: 5 | AY7: 5 | AZ7: 6 | BA7: 10 | BB7: 6 | BC7: 6 | BD7: 4
A8: 3PM | B8: =C8+SUM(G8:BD8) -> 0 | C8: 0 | D8: 0 | E8: =D8+SUM(G8:BD8) -> 0 | F8: 0 | G8: 0 | H8: 0 | I8: 0 | K8: 0 | L8: 0 | M8: 0 | N8: 0 | O8: 0 | P8: 0 | Q8: 0 | S8: 0 | U8: 0 | V8: 0 | W8: 0 | X8: 0 | Y8: 0 | Z8: 0 | AA8: 0 | AB8: 0 | AC8: 0 | AD8: 0 | AE8: 0 | AG8: 0 | AH8: 0 | AI8: 0 | AJ8: 0 | AK8: 0 | AL8: 0 | AM8: 0 | AN8: 0 | AO8: 0 | AP8: 0 | AQ8: 0 | AR8: 0 | AT8: 0 | AU8: 0 | AV8: 0 | AW8: 0 | AX8: 0 | AY8: 0 | AZ8: 0 | BA8: 0 | BB8: 0 | BC8: 0 | BD8: 0
A9: Double Doubles | B9: =C9+SUM(G9:BD9) -> 15 | C9: 14 | D9: 2 | E9: =D9+SUM(G9:BD9) -> 3 | F9: =SUM(G9:AI9) -> 0 | G9: 0 | H9: 0 | I9: 0 | K9: 0 | L9: 0 | M9: 0 | N9: 0 | O9: 0 | P9: 0 | Q9: 0 | S9: 0 | U9: 0 | V9: 0 | W9: 0 | X9: 0 | Y9: 0 | Z9: 0 | AA9: 0 | AB9: 0 | AC9: 0 | AD9: 0 | AE9: 0 | AG9: 0 | AH9: 0 | AI9: 0 | AJ9: 0 | AK9: 0 | AL9: 0 | AM9: 0 | AN9: 0 | AO9: 0 | AP9: 0 | AQ9: 0 | AR9: 0 | AT9: 0 | AU9: 0 | AV9: 0 | AW9: 0 | AX9: 0 | AY9: 1 | AZ9: 0 | BA9: 0 | BB9: 0 | BC9: 0 | BD9: 0
A10: MIN | B10: =C10+SUM(G10:BD10) -> 2607.19 | C10: 1859.8 | D10: 560 | E10: =D10+SUM(G10:BD10) -> 1307.39 | F10: 28.8 | G10: 13.58 | H10: 14.50 | I10: 13.34 | K10: 12.35 | L10: 6.28 | M10: 16.32 | N10: 27.19 | O10: 15.21 | P10: 15.52 | Q10: 10.24 | S10: 20.18 | U10: 15.01 | V10: 6.55 | W10: 18.01 | X10: 12.55 | Y10: 5.36 | Z10: 15.35 | AA10: 10.1 | AB10: 9.23 | AC10: 26.24 | AD10: 14.48 | AE10: 10.35 | AG10: 3.03 | AH10: 4.04 | AI10: 22.53 | AJ10: 20.43 | AK10: 17.19 | AL10: 9.41 | AM10: 19.51 | AN10: 6.19 | AO10: 11.46 | AP10: 22.38 | AQ10: 23.12 | AR10: 14.17 | AT10: 17.24 | AU10: 19.57 | AV10: 19.36 | AW10: 12.14 | AX10: 35.27 | AY10: 31.1 | AZ10: 37.16 | BA10: 37.09 | BB10: 29.35 | BC10: 33.13 | BD10: 36
A11: FTM | B11: =C11+SUM(G11:BD11) -> 50 | C11: 35 | D11: 10 | E11: =D11+SUM(G11:BD11) -> 25 | F11: =SUM(G11:AI11) -> 7 | G11: 0 | H11: 0 | I11: 0 | K11: 0 | L11: 0 | M11: 1 | N11: 0 | O11: 0 | P11: 0 | Q11: 0 | S11: 1 | U11: 0 | V11: 0 | W11: 0 | X11: 0 | Y11: 0 | Z11: 0 | AA11: 1 | AB11: 0 | AC11: 3 | AD11: 0 | AE11: 0 | AG11: 0 | AH11: 0 | AI11: 1 | AJ11: 0 | AK11: 1 | AL11: 0 | AM11: 0 | AN11: 0 | AO11: 0 | AP11: 0 | AQ11: 0 | AR11: 0 | AT11: 0 | AU11: 1 | AV11: 0 | AW11: 0 | AX11: 2 | AY11: 1 | AZ11: 0 | BA11: 0 | BB11: 0 | BC11: 3 | BD11: 0
A12: GP | B12: =C12+SUM(G12:BD12) -> 131 | C12: 86 | D12: 38 | E12: =D12+SUM(G12:BD12) -> 83 | F12: =SUM(G12:AI12) -> 25 | G12: 1 | H12: 1 | I12: 1 | K12: 1 | L12: 1 | M12: 1 | N12: 1 | O12: 1 | P12: 1 | Q12: 1 | S12: 1 | U12: 1 | V12: 1 | W12: 1 | X12: 1 | Y12: 1 | Z12: 1 | AA12: 1 | AB12: 1 | AC12: 1 | AD12: 1 | AE12: 1 | AG12: 1 | AH12: 1 | AI12: 1 | AJ12: 1 | AK12: 1 | AL12: 1 | AM12: 1 | AN12: 1 | AO12: 1 | AP12: 1 | AQ12: 1 | AR12: 1 | AT12: 1 | AU12: 1 | AV12: 1 | AW12: 1 | AX12: 1 | AY12: 1 | AZ12: 1 | BA12: 1 | BB12: 1 | BC12: 1 | BD12: 1
A15: PLAYOFFS: | B15: All-Time | C15: LIN (2023-24) | D15: 2025-26 | E15: 46113
A16: Points | B16: =C16+SUM(E16:BD16) -> 30 | C16: 26 | D16: =SUM(E16:AI16) -> 4 | E16: 4
A17: Rebounds | B17: =C17+SUM(E17:BD17) -> 27 | C17: 25 | D17: =SUM(E17:AI17) -> 2 | E17: 2
A18: Assists | B18: =C18+SUM(E18:BD18) -> 2 | C18: 1 | D18: =SUM(E18:AI18) -> 1 | E18: 1
A19: Steals | B19: =C19+SUM(E19:BD19) -> 3 | C19: 3 | D19: =SUM(E19:AI19) -> 0 | E19: 0
A20: Blocks | B20: =C20+SUM(E20:BD20) -> 7 | C20: 6 | D20: =SUM(E20:AI20) -> 1 | E20: 1
A21: FGM | B21: =C21+SUM(E21:BD21) -> 15 | C21: 13 | D21: =SUM(E21:AI21) -> 2 | E21: 2
A22: 3PM | B22: =C22+SUM(E22:BD22) -> 0 | C22: 0 | D22: =SUM(E22:AI22) -> 0 | E22: 0
A23: Double Doubles | B23: =C23+SUM(E23:BD23) -> 0 | C23: 0 | D23: =SUM(E23:AI23) -> 0 | E23: 0
A24: MIN | B24: =C24+SUM(E24:BD24) -> 91.45 | C24: 75 | D24: =SUM(E24:AI24) -> 16.45 | E24: 16.45
A25: FTM | B25: =C25+SUM(E25:BD25) -> 0 | C25: 0 | D25: =SUM(E25:AI25) -> 0 | E25: 0
A26: GP | B26: =C26+SUM(E26:BD26) -> 4 | C26: 3 | D26: =SUM(E26:AI26) -> 1 | E26: 1

Sheet Grant Nelson
A1: GRANT NELSON | B1: All-Time | C1: LIN | D1: 2025-26 | E1: 45968 | F1: 45970 | G1: 45975 | H1: 45976 | I1: 45983 | J1: 45985 | K1: 45987 | L1: 45990 | M1: 45992 | N1: 45996 | O1: 45997 | P1: 46000 | Q1: 46003 | R1: 46011 | S1: 46013 | T1: 46019 | U1: 45659 | V1: 45661 | W1: 45663 | X1: 45665 | Y1: 45666 | Z1: 45669 | AA1: 45671 | AB1: 46040 | AC1: 46041 | AD1: 46043 | AE1: 46045 | AF1: 46048 | AG1: 46050 | AH1: 46055 | AI1: 46058 | AJ1: 46059 | AK1: 46061 | AL1: 46063 | AM1: 46065 | AN1: 46072 | AO1: 46073 | AP1: 46078 | AQ1: 46079
A2: Points | B2: =SUM(E2:AZ2) -> 255 | C2: =SUM(E2:AZ2) -> 255 | D2: =SUM(E2:AZ2) -> 255 | F2: 8 | G2: 7 | H2: 11 | I2: 8 | J2: 2 | K2: 2 | Y2: 2 | Z2: 21 | AA2: 9 | AC2: 10 | AD2: 14 | AE2: 20 | AF2: 11 | AG2: 8 | AH2: 11 | AI2: 21 | AK2: 7 | AL2: 10 | AM2: 18 | AN2: 14 | AO2: 14 | AP2: 10 | AQ2: 17
A3: Rebounds | B3: =+SUM(E3:AZ3) -> 137 | C3: =SUM(E3:AZ3) -> 137 | D3: =SUM(E3:AZ3) -> 137 | F3: 7 | G3: 4 | H3: 5 | I3: 5 | J3: 2 | K3: 2 | Y3: 6 | Z3: 7 | AA3: 5 | AC3: 4 | AD3: 8 | AE3: 6 | AF3: 8 | AG3: 5 | AH3: 6 | AI3: 7 | AK3: 7 | AL3: 5 | AM3: 9 | AN3: 4 | AO3: 12 | AP3: 8 | AQ3: 5
A4: Assists | B4: =+SUM(E4:AZ4) -> 27 | C4: =SUM(E4:AZ4) -> 27 | D4: =SUM(E4:AZ4) -> 27 | F4: 0 | G4: 0 | H4: 0 | I4: 0 | J4: 0 | K4: 2 | Y4: 0 | Z4: 2 | AA4: 0 | AC4: 1 | AD4: 0 | AE4: 0 | AF4: 2 | AG4: 1 | AH4: 3 | AI4: 3 | AK4: 4 | AL4: 0 | AM4: 1 | AN4: 2 | AO4: 3 | AP4: 0 | AQ4: 3
A5: Steals | B5: =+SUM(E5:AZ5) -> 11 | C5: =SUM(E5:AZ5) -> 11 | D5: =SUM(E5:AZ5) -> 11 | F5: 1 | G5: 1 | H5: 0 | I5: 1 | J5: 0 | K5: 0 | Y5: 0 | Z5: 0 | AA5: 0 | AC5: 0 | AD5: 0 | AE5: 2 | AF5: 0 | AG5: 2 | AH5: 1 | AI5: 0 | AK5: 2 | AL5: 0 | AM5: 1 | AN5: 0 | AO5: 0 | AP5: 0 | AQ5: 0
A6: Blocks | B6: =+SUM(E6:AZ6) -> 17 | C6: =SUM(E6:AZ6) -> 17 | D6: =SUM(E6:AZ6) -> 17 | F6: 0 | G6: 2 | H6: 0 | I6: 0 | J6: 0 | K6: 0 | Y6: 1 | Z6: 0 | AA6: 0 | AC6: 0 | AD6: 2 | AE6: 1 | AF6: 1 | AG6: 3 | AH6: 0 | AI6: 0 | AK6: 0 | AL6: 4 | AM6: 0 | AN6: 1 | AO6: 1 | AP6: 1 | AQ6: 0
